
/*
===== MADE BY HAXMAN2'S .SCHEMATIC TO JAVA CONVERTING TOOLv0.2 ====
There is a tutorial on the forum thread on how to use this tool.
NOTE: The Block limit is 19,500 at the moment, meaning if your file is bigger then 20,000 lines, it MIGHT crash...
*/
package net.minecraft.src;
import java.util.Random;
public class WorldGenBakery extends WorldGenerator
{
    public WorldGenBakery()
    {
    }
    
 

    public boolean generate(World world, Random rand, int i, int j, int k)
    {
    	//int spawnBlockID = 4; /*2 is the block id for grass, so the structure going to spawn on grass*/
//if(world.getBlockId(i, j, k) != spawnBlockID || world.getBlockId(i, j + 1, k) != 0 || world.getBlockId(i + 12, j, k) != spawnBlockID || world.getBlockId(i + 12, j, k + 12) != spawnBlockID || world.getBlockId(i, j, k + 12) != spawnBlockID || world.getBlockId(i + 12, j + 1, k) != 0 || world.getBlockId(i + 12, j + 1, k + 12) != 0 || world.getBlockId(i, j + 1, k + 12) != 0)
if(world.getBlockId(i, j - 1, k) == Block.grass.blockID && world.getBlockId(i, j, k) == 0)
        {
        
	world.setBlock(i + 0, j + 0, k + 0, 0);
	world.setBlock(i + 0, j + 0, k + 1, 0);
	world.setBlock(i + 0, j + 0, k + 2, 0);
	world.setBlock(i + 0, j + 0, k + 3, 3);
	world.setBlock(i + 0, j + 0, k + 4, 0);
	world.setBlock(i + 0, j + 0, k + 5, 3);
	world.setBlock(i + 0, j + 0, k + 6, 2);
	world.setBlock(i + 0, j + 0, k + 7, 2);
	world.setBlock(i + 0, j + 0, k + 8, 2);
	world.setBlock(i + 0, j + 0, k + 9, 2);
	world.setBlock(i + 0, j + 0, k + 10, 3);
	world.setBlock(i + 0, j + 0, k + 11, 0);
	world.setBlock(i + 0, j + 0, k + 12, 0);
	world.setBlock(i + 0, j + 1, k + 0, 0);
	world.setBlock(i + 0, j + 1, k + 1, 0);
	world.setBlock(i + 0, j + 1, k + 2, 0);
	world.setBlock(i + 0, j + 1, k + 3, 0);
	world.setBlock(i + 0, j + 1, k + 4, 0);
	world.setBlock(i + 0, j + 1, k + 5, 0);
	world.setBlock(i + 0, j + 1, k + 6, 0);
	world.setBlock(i + 0, j + 1, k + 7, 0);
	world.setBlock(i + 0, j + 1, k + 8, 0);
	world.setBlock(i + 0, j + 1, k + 9, 0);
	world.setBlock(i + 0, j + 1, k + 10, 0);
	world.setBlock(i + 0, j + 1, k + 11, 0);
	world.setBlock(i + 0, j + 1, k + 12, 0);
	world.setBlock(i + 0, j + 2, k + 0, 0);
	world.setBlock(i + 0, j + 2, k + 1, 0);
	world.setBlock(i + 0, j + 2, k + 2, 0);
	world.setBlock(i + 0, j + 2, k + 3, 0);
	world.setBlock(i + 0, j + 2, k + 4, 0);
	world.setBlock(i + 0, j + 2, k + 5, 0);
	world.setBlock(i + 0, j + 2, k + 6, 0);
	world.setBlock(i + 0, j + 2, k + 7, 0);
	world.setBlock(i + 0, j + 2, k + 8, 0);
	world.setBlock(i + 0, j + 2, k + 9, 0);
	world.setBlock(i + 0, j + 2, k + 10, 0);
	world.setBlock(i + 0, j + 2, k + 11, 0);
	world.setBlock(i + 0, j + 2, k + 12, 0);
	world.setBlock(i + 0, j + 3, k + 0, 0);
	world.setBlock(i + 0, j + 3, k + 1, 0);
	world.setBlock(i + 0, j + 3, k + 2, 0);
	world.setBlock(i + 0, j + 3, k + 3, 0);
	world.setBlock(i + 0, j + 3, k + 4, 0);
	world.setBlock(i + 0, j + 3, k + 5, 0);
	world.setBlock(i + 0, j + 3, k + 6, 0);
	world.setBlock(i + 0, j + 3, k + 7, 0);
	world.setBlock(i + 0, j + 3, k + 8, 0);
	world.setBlock(i + 0, j + 3, k + 9, 0);
	world.setBlock(i + 0, j + 3, k + 10, 0);
	world.setBlock(i + 0, j + 3, k + 11, 0);
	world.setBlock(i + 0, j + 3, k + 12, 0);
	world.setBlock(i + 0, j + 4, k + 0, 0);
	world.setBlock(i + 0, j + 4, k + 1, 0);
	world.setBlock(i + 0, j + 4, k + 2, 0);
	world.setBlock(i + 0, j + 4, k + 3, 0);
	world.setBlock(i + 0, j + 4, k + 4, 0);
	world.setBlock(i + 0, j + 4, k + 5, 0);
	world.setBlock(i + 0, j + 4, k + 6, 0);
	world.setBlock(i + 0, j + 4, k + 7, 0);
	world.setBlock(i + 0, j + 4, k + 8, 0);
	world.setBlock(i + 0, j + 4, k + 9, 0);
	world.setBlock(i + 0, j + 4, k + 10, 0);
	world.setBlock(i + 0, j + 4, k + 11, 0);
	world.setBlock(i + 0, j + 4, k + 12, 0);
	world.setBlock(i + 0, j + 5, k + 0, 0);
	world.setBlock(i + 0, j + 5, k + 1, 0);
	world.setBlock(i + 0, j + 5, k + 2, 0);
	world.setBlock(i + 0, j + 5, k + 3, 0);
	world.setBlock(i + 0, j + 5, k + 4, 0);
	world.setBlock(i + 0, j + 5, k + 5, 0);
	world.setBlock(i + 0, j + 5, k + 6, 0);
	world.setBlock(i + 0, j + 5, k + 7, 0);
	world.setBlock(i + 0, j + 5, k + 8, 0);
	world.setBlock(i + 0, j + 5, k + 9, 0);
	world.setBlock(i + 0, j + 5, k + 10, 0);
	world.setBlock(i + 0, j + 5, k + 11, 0);
	world.setBlock(i + 0, j + 5, k + 12, 0);
	world.setBlock(i + 0, j + 6, k + 0, 0);
	world.setBlock(i + 0, j + 6, k + 1, 0);
	world.setBlock(i + 0, j + 6, k + 2, 0);
	world.setBlock(i + 0, j + 6, k + 3, 0);
	world.setBlock(i + 0, j + 6, k + 4, 0);
	world.setBlock(i + 0, j + 6, k + 5, 0);
	world.setBlock(i + 0, j + 6, k + 6, 0);
	world.setBlock(i + 0, j + 6, k + 7, 0);
	world.setBlock(i + 0, j + 6, k + 8, 0);
	world.setBlock(i + 0, j + 6, k + 9, 0);
	world.setBlock(i + 0, j + 6, k + 10, 0);
	world.setBlock(i + 0, j + 6, k + 11, 0);
	world.setBlock(i + 0, j + 6, k + 12, 0);
	world.setBlock(i + 0, j + 7, k + 0, 0);
	world.setBlock(i + 0, j + 7, k + 1, 0);
	world.setBlock(i + 0, j + 7, k + 2, 0);
	world.setBlock(i + 0, j + 7, k + 3, 0);
	world.setBlock(i + 0, j + 7, k + 4, 0);
	world.setBlock(i + 0, j + 7, k + 5, 0);
	world.setBlock(i + 0, j + 7, k + 6, 0);
	world.setBlock(i + 0, j + 7, k + 7, 0);
	world.setBlock(i + 0, j + 7, k + 8, 0);
	world.setBlock(i + 0, j + 7, k + 9, 0);
	world.setBlock(i + 0, j + 7, k + 10, 0);
	world.setBlock(i + 0, j + 7, k + 11, 0);
	world.setBlock(i + 0, j + 7, k + 12, 0);
	world.setBlock(i + 0, j + 8, k + 0, 0);
	world.setBlock(i + 0, j + 8, k + 1, 0);
	world.setBlock(i + 0, j + 8, k + 2, 0);
	world.setBlock(i + 0, j + 8, k + 3, 0);
	world.setBlock(i + 0, j + 8, k + 4, 0);
	world.setBlock(i + 0, j + 8, k + 5, 0);
	world.setBlock(i + 0, j + 8, k + 6, 0);
	world.setBlock(i + 0, j + 8, k + 7, 0);
	world.setBlock(i + 0, j + 8, k + 8, 0);
	world.setBlock(i + 0, j + 8, k + 9, 0);
	world.setBlock(i + 0, j + 8, k + 10, 0);
	world.setBlock(i + 0, j + 8, k + 11, 0);
	world.setBlock(i + 0, j + 8, k + 12, 0);
	world.setBlock(i + 0, j + 9, k + 0, 0);
	world.setBlock(i + 0, j + 9, k + 1, 0);
	world.setBlock(i + 0, j + 9, k + 2, 0);
	world.setBlock(i + 0, j + 9, k + 3, 0);
	world.setBlock(i + 0, j + 9, k + 4, 0);
	world.setBlock(i + 0, j + 9, k + 5, 0);
	world.setBlock(i + 0, j + 9, k + 6, 0);
	world.setBlock(i + 0, j + 9, k + 7, 0);
	world.setBlock(i + 0, j + 9, k + 8, 0);
	world.setBlock(i + 0, j + 9, k + 9, 0);
	world.setBlock(i + 0, j + 9, k + 10, 0);
	world.setBlock(i + 0, j + 9, k + 11, 0);
	world.setBlock(i + 0, j + 9, k + 12, 0);
	world.setBlock(i + 0, j + 10, k + 0, 0);
	world.setBlock(i + 0, j + 10, k + 1, 0);
	world.setBlock(i + 0, j + 10, k + 2, 0);
	world.setBlock(i + 0, j + 10, k + 3, 0);
	world.setBlock(i + 0, j + 10, k + 4, 0);
	world.setBlock(i + 0, j + 10, k + 5, 0);
	world.setBlock(i + 0, j + 10, k + 6, 0);
	world.setBlock(i + 0, j + 10, k + 7, 0);
	world.setBlock(i + 0, j + 10, k + 8, 0);
	world.setBlock(i + 0, j + 10, k + 9, 0);
	world.setBlock(i + 0, j + 10, k + 10, 0);
	world.setBlock(i + 0, j + 10, k + 11, 0);
	world.setBlock(i + 0, j + 10, k + 12, 0);
	world.setBlock(i + 0, j + 11, k + 0, 0);
	world.setBlock(i + 0, j + 11, k + 1, 0);
	world.setBlock(i + 0, j + 11, k + 2, 0);
	world.setBlock(i + 0, j + 11, k + 3, 0);
	world.setBlock(i + 0, j + 11, k + 4, 0);
	world.setBlock(i + 0, j + 11, k + 5, 0);
	world.setBlock(i + 0, j + 11, k + 6, 0);
	world.setBlock(i + 0, j + 11, k + 7, 0);
	world.setBlock(i + 0, j + 11, k + 8, 0);
	world.setBlock(i + 0, j + 11, k + 9, 0);
	world.setBlock(i + 0, j + 11, k + 10, 0);
	world.setBlock(i + 0, j + 11, k + 11, 0);
	world.setBlock(i + 0, j + 11, k + 12, 0);
	world.setBlock(i + 0, j + 12, k + 0, 0);
	world.setBlock(i + 0, j + 12, k + 1, 0);
	world.setBlock(i + 0, j + 12, k + 2, 0);
	world.setBlock(i + 0, j + 12, k + 3, 0);
	world.setBlock(i + 0, j + 12, k + 4, 0);
	world.setBlock(i + 0, j + 12, k + 5, 0);
	world.setBlock(i + 0, j + 12, k + 6, 0);
	world.setBlock(i + 0, j + 12, k + 7, 0);
	world.setBlock(i + 0, j + 12, k + 8, 0);
	world.setBlock(i + 0, j + 12, k + 9, 0);
	world.setBlock(i + 0, j + 12, k + 10, 0);
	world.setBlock(i + 0, j + 12, k + 11, 0);
	world.setBlock(i + 0, j + 12, k + 12, 0);
	world.setBlock(i + 0, j + 13, k + 0, 0);
	world.setBlock(i + 0, j + 13, k + 1, 0);
	world.setBlock(i + 0, j + 13, k + 2, 0);
	world.setBlock(i + 0, j + 13, k + 3, 53);
	world.setBlockMetadata(i + 0, j + 13, k + 3, 2);
	world.setBlock(i + 0, j + 13, k + 4, 5);
	world.setBlock(i + 0, j + 13, k + 5, 53);
	world.setBlockMetadata(i + 0, j + 13, k + 5, 3);
	world.setBlock(i + 0, j + 13, k + 6, 0);
	world.setBlock(i + 0, j + 13, k + 7, 0);
	world.setBlock(i + 0, j + 13, k + 8, 0);
	world.setBlock(i + 0, j + 13, k + 9, 0);
	world.setBlock(i + 0, j + 13, k + 10, 0);
	world.setBlock(i + 0, j + 13, k + 11, 0);
	world.setBlock(i + 0, j + 13, k + 12, 0);
	world.setBlock(i + 1, j + 0, k + 0, 0);
	world.setBlock(i + 1, j + 0, k + 1, 0);
	world.setBlock(i + 1, j + 0, k + 2, 3);
	world.setBlock(i + 1, j + 0, k + 3, 3);
	world.setBlock(i + 1, j + 0, k + 4, 3);
	world.setBlock(i + 1, j + 0, k + 5, 2);
	world.setBlock(i + 1, j + 0, k + 6, 2);
	world.setBlock(i + 1, j + 0, k + 7, 2);
	world.setBlock(i + 1, j + 0, k + 8, 2);
	world.setBlock(i + 1, j + 0, k + 9, 2);
	world.setBlock(i + 1, j + 0, k + 10, 2);
	world.setBlock(i + 1, j + 0, k + 11, 3);
	world.setBlock(i + 1, j + 0, k + 12, 0);
	world.setBlock(i + 1, j + 1, k + 0, 0);
	world.setBlock(i + 1, j + 1, k + 1, 0);
	world.setBlock(i + 1, j + 1, k + 2, 0);
	world.setBlock(i + 1, j + 1, k + 3, 0);
	world.setBlock(i + 1, j + 1, k + 4, 0);
	world.setBlock(i + 1, j + 1, k + 5, 0);
	world.setBlock(i + 1, j + 1, k + 6, 0);
	world.setBlock(i + 1, j + 1, k + 7, 0);
	world.setBlock(i + 1, j + 1, k + 8, 0);
	world.setBlock(i + 1, j + 1, k + 9, 0);
	world.setBlock(i + 1, j + 1, k + 10, 0);
	world.setBlock(i + 1, j + 1, k + 11, 0);
	world.setBlock(i + 1, j + 1, k + 12, 0);
	world.setBlock(i + 1, j + 2, k + 0, 0);
	world.setBlock(i + 1, j + 2, k + 1, 0);
	world.setBlock(i + 1, j + 2, k + 2, 0);
	world.setBlock(i + 1, j + 2, k + 3, 0);
	world.setBlock(i + 1, j + 2, k + 4, 0);
	world.setBlock(i + 1, j + 2, k + 5, 0);
	world.setBlock(i + 1, j + 2, k + 6, 0);
	world.setBlock(i + 1, j + 2, k + 7, 0);
	world.setBlock(i + 1, j + 2, k + 8, 0);
	world.setBlock(i + 1, j + 2, k + 9, 0);
	world.setBlock(i + 1, j + 2, k + 10, 0);
	world.setBlock(i + 1, j + 2, k + 11, 0);
	world.setBlock(i + 1, j + 2, k + 12, 0);
	world.setBlock(i + 1, j + 3, k + 0, 0);
	world.setBlock(i + 1, j + 3, k + 1, 0);
	world.setBlock(i + 1, j + 3, k + 2, 0);
	world.setBlock(i + 1, j + 3, k + 3, 0);
	world.setBlock(i + 1, j + 3, k + 4, 0);
	world.setBlock(i + 1, j + 3, k + 5, 0);
	world.setBlock(i + 1, j + 3, k + 6, 0);
	world.setBlock(i + 1, j + 3, k + 7, 0);
	world.setBlock(i + 1, j + 3, k + 8, 0);
	world.setBlock(i + 1, j + 3, k + 9, 0);
	world.setBlock(i + 1, j + 3, k + 10, 0);
	world.setBlock(i + 1, j + 3, k + 11, 0);
	world.setBlock(i + 1, j + 3, k + 12, 0);
	world.setBlock(i + 1, j + 4, k + 0, 0);
	world.setBlock(i + 1, j + 4, k + 1, 0);
	world.setBlock(i + 1, j + 4, k + 2, 0);
	world.setBlock(i + 1, j + 4, k + 3, 0);
	world.setBlock(i + 1, j + 4, k + 4, 0);
	world.setBlock(i + 1, j + 4, k + 5, 0);
	world.setBlock(i + 1, j + 4, k + 6, 0);
	world.setBlock(i + 1, j + 4, k + 7, 0);
	world.setBlock(i + 1, j + 4, k + 8, 0);
	world.setBlock(i + 1, j + 4, k + 9, 0);
	world.setBlock(i + 1, j + 4, k + 10, 0);
	world.setBlock(i + 1, j + 4, k + 11, 0);
	world.setBlock(i + 1, j + 4, k + 12, 0);
	world.setBlock(i + 1, j + 5, k + 0, 0);
	world.setBlock(i + 1, j + 5, k + 1, 0);
	world.setBlock(i + 1, j + 5, k + 2, 0);
	world.setBlock(i + 1, j + 5, k + 3, 0);
	world.setBlock(i + 1, j + 5, k + 4, 0);
	world.setBlock(i + 1, j + 5, k + 5, 0);
	world.setBlock(i + 1, j + 5, k + 6, 0);
	world.setBlock(i + 1, j + 5, k + 7, 0);
	world.setBlock(i + 1, j + 5, k + 8, 0);
	world.setBlock(i + 1, j + 5, k + 9, 0);
	world.setBlock(i + 1, j + 5, k + 10, 0);
	world.setBlock(i + 1, j + 5, k + 11, 0);
	world.setBlock(i + 1, j + 5, k + 12, 0);
	world.setBlock(i + 1, j + 6, k + 0, 0);
	world.setBlock(i + 1, j + 6, k + 1, 0);
	world.setBlock(i + 1, j + 6, k + 2, 0);
	world.setBlock(i + 1, j + 6, k + 3, 0);
	world.setBlock(i + 1, j + 6, k + 4, 0);
	world.setBlock(i + 1, j + 6, k + 5, 0);
	world.setBlock(i + 1, j + 6, k + 6, 0);
	world.setBlock(i + 1, j + 6, k + 7, 0);
	world.setBlock(i + 1, j + 6, k + 8, 0);
	world.setBlock(i + 1, j + 6, k + 9, 0);
	world.setBlock(i + 1, j + 6, k + 10, 0);
	world.setBlock(i + 1, j + 6, k + 11, 0);
	world.setBlock(i + 1, j + 6, k + 12, 0);
	world.setBlock(i + 1, j + 7, k + 0, 0);
	world.setBlock(i + 1, j + 7, k + 1, 0);
	world.setBlock(i + 1, j + 7, k + 2, 0);
	world.setBlock(i + 1, j + 7, k + 3, 0);
	world.setBlock(i + 1, j + 7, k + 4, 0);
	world.setBlock(i + 1, j + 7, k + 5, 0);
	world.setBlock(i + 1, j + 7, k + 6, 0);
	world.setBlock(i + 1, j + 7, k + 7, 0);
	world.setBlock(i + 1, j + 7, k + 8, 0);
	world.setBlock(i + 1, j + 7, k + 9, 0);
	world.setBlock(i + 1, j + 7, k + 10, 0);
	world.setBlock(i + 1, j + 7, k + 11, 0);
	world.setBlock(i + 1, j + 7, k + 12, 0);
	world.setBlock(i + 1, j + 8, k + 0, 0);
	world.setBlock(i + 1, j + 8, k + 1, 0);
	world.setBlock(i + 1, j + 8, k + 2, 0);
	world.setBlock(i + 1, j + 8, k + 3, 0);
	world.setBlock(i + 1, j + 8, k + 4, 0);
	world.setBlock(i + 1, j + 8, k + 5, 0);
	world.setBlock(i + 1, j + 8, k + 6, 0);
	world.setBlock(i + 1, j + 8, k + 7, 0);
	world.setBlock(i + 1, j + 8, k + 8, 0);
	world.setBlock(i + 1, j + 8, k + 9, 0);
	world.setBlock(i + 1, j + 8, k + 10, 0);
	world.setBlock(i + 1, j + 8, k + 11, 0);
	world.setBlock(i + 1, j + 8, k + 12, 0);
	world.setBlock(i + 1, j + 9, k + 0, 0);
	world.setBlock(i + 1, j + 9, k + 1, 0);
	world.setBlock(i + 1, j + 9, k + 2, 0);
	world.setBlock(i + 1, j + 9, k + 3, 0);
	world.setBlock(i + 1, j + 9, k + 4, 0);
	world.setBlock(i + 1, j + 9, k + 5, 0);
	world.setBlock(i + 1, j + 9, k + 6, 0);
	world.setBlock(i + 1, j + 9, k + 7, 0);
	world.setBlock(i + 1, j + 9, k + 8, 0);
	world.setBlock(i + 1, j + 9, k + 9, 0);
	world.setBlock(i + 1, j + 9, k + 10, 0);
	world.setBlock(i + 1, j + 9, k + 11, 0);
	world.setBlock(i + 1, j + 9, k + 12, 0);
	world.setBlock(i + 1, j + 10, k + 0, 0);
	world.setBlock(i + 1, j + 10, k + 1, 0);
	world.setBlock(i + 1, j + 10, k + 2, 0);
	world.setBlock(i + 1, j + 10, k + 3, 0);
	world.setBlock(i + 1, j + 10, k + 4, 0);
	world.setBlock(i + 1, j + 10, k + 5, 0);
	world.setBlock(i + 1, j + 10, k + 6, 0);
	world.setBlock(i + 1, j + 10, k + 7, 0);
	world.setBlock(i + 1, j + 10, k + 8, 0);
	world.setBlock(i + 1, j + 10, k + 9, 0);
	world.setBlock(i + 1, j + 10, k + 10, 0);
	world.setBlock(i + 1, j + 10, k + 11, 0);
	world.setBlock(i + 1, j + 10, k + 12, 0);
	world.setBlock(i + 1, j + 11, k + 0, 0);
	world.setBlock(i + 1, j + 11, k + 1, 0);
	world.setBlock(i + 1, j + 11, k + 2, 0);
	world.setBlock(i + 1, j + 11, k + 3, 0);
	world.setBlock(i + 1, j + 11, k + 4, 0);
	world.setBlock(i + 1, j + 11, k + 5, 0);
	world.setBlock(i + 1, j + 11, k + 6, 0);
	world.setBlock(i + 1, j + 11, k + 7, 0);
	world.setBlock(i + 1, j + 11, k + 8, 0);
	world.setBlock(i + 1, j + 11, k + 9, 0);
	world.setBlock(i + 1, j + 11, k + 10, 0);
	world.setBlock(i + 1, j + 11, k + 11, 0);
	world.setBlock(i + 1, j + 11, k + 12, 0);
	world.setBlock(i + 1, j + 12, k + 0, 0);
	world.setBlock(i + 1, j + 12, k + 1, 0);
	world.setBlock(i + 1, j + 12, k + 2, 53);
	world.setBlockMetadata(i + 1, j + 12, k + 2, 2);
	world.setBlock(i + 1, j + 12, k + 3, 0);
	world.setBlock(i + 1, j + 12, k + 4, 0);
	world.setBlock(i + 1, j + 12, k + 5, 0);
	world.setBlock(i + 1, j + 12, k + 6, 53);
	world.setBlockMetadata(i + 1, j + 12, k + 6, 3);
	world.setBlock(i + 1, j + 12, k + 7, 0);
	world.setBlock(i + 1, j + 12, k + 8, 0);
	world.setBlock(i + 1, j + 12, k + 9, 0);
	world.setBlock(i + 1, j + 12, k + 10, 0);
	world.setBlock(i + 1, j + 12, k + 11, 0);
	world.setBlock(i + 1, j + 12, k + 12, 0);
	world.setBlock(i + 1, j + 13, k + 0, 0);
	world.setBlock(i + 1, j + 13, k + 1, 0);
	world.setBlock(i + 1, j + 13, k + 2, 0);
	world.setBlock(i + 1, j + 13, k + 3, 53);
	world.setBlockMetadata(i + 1, j + 13, k + 3, 2);
	world.setBlock(i + 1, j + 13, k + 4, 5);
	world.setBlock(i + 1, j + 13, k + 5, 53);
	world.setBlockMetadata(i + 1, j + 13, k + 5, 3);
	world.setBlock(i + 1, j + 13, k + 6, 0);
	world.setBlock(i + 1, j + 13, k + 7, 0);
	world.setBlock(i + 1, j + 13, k + 8, 0);
	world.setBlock(i + 1, j + 13, k + 9, 0);
	world.setBlock(i + 1, j + 13, k + 10, 0);
	world.setBlock(i + 1, j + 13, k + 11, 0);
	world.setBlock(i + 1, j + 13, k + 12, 0);
	world.setBlock(i + 2, j + 0, k + 0, 0);
	world.setBlock(i + 2, j + 0, k + 1, 3);
	world.setBlock(i + 2, j + 0, k + 2, 3);
	world.setBlock(i + 2, j + 0, k + 3, 2);
	world.setBlock(i + 2, j + 0, k + 4, 2);
	world.setBlock(i + 2, j + 0, k + 5, 2);
	world.setBlock(i + 2, j + 0, k + 6, 2);
	world.setBlock(i + 2, j + 0, k + 7, 2);
	world.setBlock(i + 2, j + 0, k + 8, 2);
	world.setBlock(i + 2, j + 0, k + 9, 2);
	world.setBlock(i + 2, j + 0, k + 10, 2);
	world.setBlock(i + 2, j + 0, k + 11, 2);
	world.setBlock(i + 2, j + 0, k + 12, 3);
	world.setBlock(i + 2, j + 1, k + 0, 0);
	world.setBlock(i + 2, j + 1, k + 1, 0);
	world.setBlock(i + 2, j + 1, k + 2, 0);
	world.setBlock(i + 2, j + 1, k + 3, 0);
	world.setBlock(i + 2, j + 1, k + 4, 0);
	world.setBlock(i + 2, j + 1, k + 5, 0);
	world.setBlock(i + 2, j + 1, k + 6, 0);
	world.setBlock(i + 2, j + 1, k + 7, 0);
	world.setBlock(i + 2, j + 1, k + 8, 0);
	world.setBlock(i + 2, j + 1, k + 9, 0);
	world.setBlock(i + 2, j + 1, k + 10, 0);
	world.setBlock(i + 2, j + 1, k + 11, 0);
	world.setBlock(i + 2, j + 1, k + 12, 0);
	world.setBlock(i + 2, j + 2, k + 0, 0);
	world.setBlock(i + 2, j + 2, k + 1, 0);
	world.setBlock(i + 2, j + 2, k + 2, 0);
	world.setBlock(i + 2, j + 2, k + 3, 0);
	world.setBlock(i + 2, j + 2, k + 4, 0);
	world.setBlock(i + 2, j + 2, k + 5, 0);
	world.setBlock(i + 2, j + 2, k + 6, 0);
	world.setBlock(i + 2, j + 2, k + 7, 0);
	world.setBlock(i + 2, j + 2, k + 8, 0);
	world.setBlock(i + 2, j + 2, k + 9, 0);
	world.setBlock(i + 2, j + 2, k + 10, 0);
	world.setBlock(i + 2, j + 2, k + 11, 0);
	world.setBlock(i + 2, j + 2, k + 12, 0);
	world.setBlock(i + 2, j + 3, k + 0, 0);
	world.setBlock(i + 2, j + 3, k + 1, 0);
	world.setBlock(i + 2, j + 3, k + 2, 0);
	world.setBlock(i + 2, j + 3, k + 3, 0);
	world.setBlock(i + 2, j + 3, k + 4, 0);
	world.setBlock(i + 2, j + 3, k + 5, 0);
	world.setBlock(i + 2, j + 3, k + 6, 0);
	world.setBlock(i + 2, j + 3, k + 7, 0);
	world.setBlock(i + 2, j + 3, k + 8, 0);
	world.setBlock(i + 2, j + 3, k + 9, 0);
	world.setBlock(i + 2, j + 3, k + 10, 0);
	world.setBlock(i + 2, j + 3, k + 11, 0);
	world.setBlock(i + 2, j + 3, k + 12, 0);
	world.setBlock(i + 2, j + 4, k + 0, 0);
	world.setBlock(i + 2, j + 4, k + 1, 0);
	world.setBlock(i + 2, j + 4, k + 2, 0);
	world.setBlock(i + 2, j + 4, k + 3, 0);
	world.setBlock(i + 2, j + 4, k + 4, 0);
	world.setBlock(i + 2, j + 4, k + 5, 0);
	world.setBlock(i + 2, j + 4, k + 6, 0);
	world.setBlock(i + 2, j + 4, k + 7, 0);
	world.setBlock(i + 2, j + 4, k + 8, 0);
	world.setBlock(i + 2, j + 4, k + 9, 0);
	world.setBlock(i + 2, j + 4, k + 10, 0);
	world.setBlock(i + 2, j + 4, k + 11, 0);
	world.setBlock(i + 2, j + 4, k + 12, 0);
	world.setBlock(i + 2, j + 5, k + 0, 0);
	world.setBlock(i + 2, j + 5, k + 1, 0);
	world.setBlock(i + 2, j + 5, k + 2, 0);
	world.setBlock(i + 2, j + 5, k + 3, 0);
	world.setBlock(i + 2, j + 5, k + 4, 0);
	world.setBlock(i + 2, j + 5, k + 5, 0);
	world.setBlock(i + 2, j + 5, k + 6, 0);
	world.setBlock(i + 2, j + 5, k + 7, 0);
	world.setBlock(i + 2, j + 5, k + 8, 0);
	world.setBlock(i + 2, j + 5, k + 9, 0);
	world.setBlock(i + 2, j + 5, k + 10, 0);
	world.setBlock(i + 2, j + 5, k + 11, 0);
	world.setBlock(i + 2, j + 5, k + 12, 0);
	world.setBlock(i + 2, j + 6, k + 0, 0);
	world.setBlock(i + 2, j + 6, k + 1, 0);
	world.setBlock(i + 2, j + 6, k + 2, 0);
	world.setBlock(i + 2, j + 6, k + 3, 0);
	world.setBlock(i + 2, j + 6, k + 4, 0);
	world.setBlock(i + 2, j + 6, k + 5, 0);
	world.setBlock(i + 2, j + 6, k + 6, 0);
	world.setBlock(i + 2, j + 6, k + 7, 0);
	world.setBlock(i + 2, j + 6, k + 8, 0);
	world.setBlock(i + 2, j + 6, k + 9, 0);
	world.setBlock(i + 2, j + 6, k + 10, 0);
	world.setBlock(i + 2, j + 6, k + 11, 0);
	world.setBlock(i + 2, j + 6, k + 12, 0);
	world.setBlock(i + 2, j + 7, k + 0, 0);
	world.setBlock(i + 2, j + 7, k + 1, 0);
	world.setBlock(i + 2, j + 7, k + 2, 0);
	world.setBlock(i + 2, j + 7, k + 3, 0);
	world.setBlock(i + 2, j + 7, k + 4, 0);
	world.setBlock(i + 2, j + 7, k + 5, 0);
	world.setBlock(i + 2, j + 7, k + 6, 0);
	world.setBlock(i + 2, j + 7, k + 7, 0);
	world.setBlock(i + 2, j + 7, k + 8, 0);
	world.setBlock(i + 2, j + 7, k + 9, 0);
	world.setBlock(i + 2, j + 7, k + 10, 0);
	world.setBlock(i + 2, j + 7, k + 11, 0);
	world.setBlock(i + 2, j + 7, k + 12, 0);
	world.setBlock(i + 2, j + 8, k + 0, 0);
	world.setBlock(i + 2, j + 8, k + 1, 0);
	world.setBlock(i + 2, j + 8, k + 2, 0);
	world.setBlock(i + 2, j + 8, k + 3, 0);
	world.setBlock(i + 2, j + 8, k + 4, 0);
	world.setBlock(i + 2, j + 8, k + 5, 0);
	world.setBlock(i + 2, j + 8, k + 6, 0);
	world.setBlock(i + 2, j + 8, k + 7, 0);
	world.setBlock(i + 2, j + 8, k + 8, 0);
	world.setBlock(i + 2, j + 8, k + 9, 0);
	world.setBlock(i + 2, j + 8, k + 10, 0);
	world.setBlock(i + 2, j + 8, k + 11, 0);
	world.setBlock(i + 2, j + 8, k + 12, 0);
	world.setBlock(i + 2, j + 9, k + 0, 0);
	world.setBlock(i + 2, j + 9, k + 1, 0);
	world.setBlock(i + 2, j + 9, k + 2, 0);
	world.setBlock(i + 2, j + 9, k + 3, 0);
	world.setBlock(i + 2, j + 9, k + 4, 0);
	world.setBlock(i + 2, j + 9, k + 5, 0);
	world.setBlock(i + 2, j + 9, k + 6, 0);
	world.setBlock(i + 2, j + 9, k + 7, 0);
	world.setBlock(i + 2, j + 9, k + 8, 0);
	world.setBlock(i + 2, j + 9, k + 9, 0);
	world.setBlock(i + 2, j + 9, k + 10, 0);
	world.setBlock(i + 2, j + 9, k + 11, 0);
	world.setBlock(i + 2, j + 9, k + 12, 0);
	world.setBlock(i + 2, j + 10, k + 0, 0);
	world.setBlock(i + 2, j + 10, k + 1, 0);
	world.setBlock(i + 2, j + 10, k + 2, 0);
	world.setBlock(i + 2, j + 10, k + 3, 0);
	world.setBlock(i + 2, j + 10, k + 4, 0);
	world.setBlock(i + 2, j + 10, k + 5, 0);
	world.setBlock(i + 2, j + 10, k + 6, 0);
	world.setBlock(i + 2, j + 10, k + 7, 0);
	world.setBlock(i + 2, j + 10, k + 8, 0);
	world.setBlock(i + 2, j + 10, k + 9, 0);
	world.setBlock(i + 2, j + 10, k + 10, 0);
	world.setBlock(i + 2, j + 10, k + 11, 0);
	world.setBlock(i + 2, j + 10, k + 12, 0);
	world.setBlock(i + 2, j + 11, k + 0, 0);
	world.setBlock(i + 2, j + 11, k + 1, 53);
	world.setBlockMetadata(i + 2, j + 11, k + 1, 2);
	world.setBlock(i + 2, j + 11, k + 2, 0);
	world.setBlock(i + 2, j + 11, k + 3, 0);
	world.setBlock(i + 2, j + 11, k + 4, 0);
	world.setBlock(i + 2, j + 11, k + 5, 0);
	world.setBlock(i + 2, j + 11, k + 6, 0);
	world.setBlock(i + 2, j + 11, k + 7, 53);
	world.setBlockMetadata(i + 2, j + 11, k + 7, 3);
	world.setBlock(i + 2, j + 11, k + 8, 0);
	world.setBlock(i + 2, j + 11, k + 9, 0);
	world.setBlock(i + 2, j + 11, k + 10, 0);
	world.setBlock(i + 2, j + 11, k + 11, 0);
	world.setBlock(i + 2, j + 11, k + 12, 0);
	world.setBlock(i + 2, j + 12, k + 0, 0);
	world.setBlock(i + 2, j + 12, k + 1, 0);
	world.setBlock(i + 2, j + 12, k + 2, 53);
	world.setBlockMetadata(i + 2, j + 12, k + 2, 2);
	world.setBlock(i + 2, j + 12, k + 3, 0);
	world.setBlock(i + 2, j + 12, k + 4, 0);
	world.setBlock(i + 2, j + 12, k + 5, 0);
	world.setBlock(i + 2, j + 12, k + 6, 53);
	world.setBlockMetadata(i + 2, j + 12, k + 6, 3);
	world.setBlock(i + 2, j + 12, k + 7, 0);
	world.setBlock(i + 2, j + 12, k + 8, 0);
	world.setBlock(i + 2, j + 12, k + 9, 0);
	world.setBlock(i + 2, j + 12, k + 10, 0);
	world.setBlock(i + 2, j + 12, k + 11, 0);
	world.setBlock(i + 2, j + 12, k + 12, 0);
	world.setBlock(i + 2, j + 13, k + 0, 0);
	world.setBlock(i + 2, j + 13, k + 1, 0);
	world.setBlock(i + 2, j + 13, k + 2, 0);
	world.setBlock(i + 2, j + 13, k + 3, 53);
	world.setBlockMetadata(i + 2, j + 13, k + 3, 2);
	world.setBlock(i + 2, j + 13, k + 4, 5);
	world.setBlock(i + 2, j + 13, k + 5, 53);
	world.setBlockMetadata(i + 2, j + 13, k + 5, 3);
	world.setBlock(i + 2, j + 13, k + 6, 0);
	world.setBlock(i + 2, j + 13, k + 7, 0);
	world.setBlock(i + 2, j + 13, k + 8, 0);
	world.setBlock(i + 2, j + 13, k + 9, 0);
	world.setBlock(i + 2, j + 13, k + 10, 0);
	world.setBlock(i + 2, j + 13, k + 11, 0);
	world.setBlock(i + 2, j + 13, k + 12, 0);
	world.setBlock(i + 3, j + 0, k + 0, 3);
	world.setBlock(i + 3, j + 0, k + 1, 3);
	world.setBlock(i + 3, j + 0, k + 2, 3);
	world.setBlock(i + 3, j + 0, k + 3, 3);
	world.setBlock(i + 3, j + 0, k + 4, 3);
	world.setBlock(i + 3, j + 0, k + 5, 4);
	world.setBlock(i + 3, j + 0, k + 6, 4);
	world.setBlock(i + 3, j + 0, k + 7, 4);
	world.setBlock(i + 3, j + 0, k + 8, 4);
	world.setBlock(i + 3, j + 0, k + 9, 4);
	world.setBlock(i + 3, j + 0, k + 10, 4);
	world.setBlock(i + 3, j + 0, k + 11, 2);
	world.setBlock(i + 3, j + 0, k + 12, 3);
	world.setBlock(i + 3, j + 1, k + 0, 0);
	world.setBlock(i + 3, j + 1, k + 1, 0);
	world.setBlock(i + 3, j + 1, k + 2, 4);
	world.setBlock(i + 3, j + 1, k + 3, 4);
	world.setBlock(i + 3, j + 1, k + 4, 4);
	world.setBlock(i + 3, j + 1, k + 5, 4);
	world.setBlock(i + 3, j + 1, k + 6, 4);
	world.setBlock(i + 3, j + 1, k + 7, 4);
	world.setBlock(i + 3, j + 1, k + 8, 4);
	world.setBlock(i + 3, j + 1, k + 9, 4);
	world.setBlock(i + 3, j + 1, k + 10, 4);
	world.setBlock(i + 3, j + 1, k + 11, 0);
	world.setBlock(i + 3, j + 1, k + 12, 0);
	world.setBlock(i + 3, j + 2, k + 0, 0);
	world.setBlock(i + 3, j + 2, k + 1, 0);
	world.setBlock(i + 3, j + 2, k + 2, 17);
	world.setBlockMetadata(i + 3, j + 2, k + 2, 1);
	world.setBlock(i + 3, j + 2, k + 3, 5);
	world.setBlock(i + 3, j + 2, k + 4, 5);
	world.setBlock(i + 3, j + 2, k + 5, 5);
	world.setBlock(i + 3, j + 2, k + 6, 5);
	world.setBlock(i + 3, j + 2, k + 7, 5);
	world.setBlock(i + 3, j + 2, k + 8, 5);
	world.setBlock(i + 3, j + 2, k + 9, 5);
	world.setBlock(i + 3, j + 2, k + 10, 17);
	world.setBlockMetadata(i + 3, j + 2, k + 10, 1);
	world.setBlock(i + 3, j + 2, k + 11, 0);
	world.setBlock(i + 3, j + 2, k + 12, 0);
	world.setBlock(i + 3, j + 3, k + 0, 0);
	world.setBlock(i + 3, j + 3, k + 1, 0);
	world.setBlock(i + 3, j + 3, k + 2, 17);
	world.setBlockMetadata(i + 3, j + 3, k + 2, 1);
	world.setBlock(i + 3, j + 3, k + 3, 102);
	world.setBlock(i + 3, j + 3, k + 4, 102);
	world.setBlock(i + 3, j + 3, k + 5, 5);
	world.setBlock(i + 3, j + 3, k + 6, 5);
	world.setBlock(i + 3, j + 3, k + 7, 5);
	world.setBlock(i + 3, j + 3, k + 8, 5);
	world.setBlock(i + 3, j + 3, k + 9, 5);
	world.setBlock(i + 3, j + 3, k + 10, 17);
	world.setBlockMetadata(i + 3, j + 3, k + 10, 1);
	world.setBlock(i + 3, j + 3, k + 11, 0);
	world.setBlock(i + 3, j + 3, k + 12, 0);
	world.setBlock(i + 3, j + 4, k + 0, 0);
	world.setBlock(i + 3, j + 4, k + 1, 0);
	world.setBlock(i + 3, j + 4, k + 2, 17);
	world.setBlockMetadata(i + 3, j + 4, k + 2, 1);
	world.setBlock(i + 3, j + 4, k + 3, 102);
	world.setBlock(i + 3, j + 4, k + 4, 102);
	world.setBlock(i + 3, j + 4, k + 5, 5);
	world.setBlock(i + 3, j + 4, k + 6, 5);
	world.setBlock(i + 3, j + 4, k + 7, 5);
	world.setBlock(i + 3, j + 4, k + 8, 5);
	world.setBlock(i + 3, j + 4, k + 9, 5);
	world.setBlock(i + 3, j + 4, k + 10, 17);
	world.setBlockMetadata(i + 3, j + 4, k + 10, 1);
	world.setBlock(i + 3, j + 4, k + 11, 0);
	world.setBlock(i + 3, j + 4, k + 12, 0);
	world.setBlock(i + 3, j + 5, k + 0, 0);
	world.setBlock(i + 3, j + 5, k + 1, 0);
	world.setBlock(i + 3, j + 5, k + 2, 17);
	world.setBlockMetadata(i + 3, j + 5, k + 2, 1);
	world.setBlock(i + 3, j + 5, k + 3, 5);
	world.setBlock(i + 3, j + 5, k + 4, 5);
	world.setBlock(i + 3, j + 5, k + 5, 5);
	world.setBlock(i + 3, j + 5, k + 6, 5);
	world.setBlock(i + 3, j + 5, k + 7, 5);
	world.setBlock(i + 3, j + 5, k + 8, 5);
	world.setBlock(i + 3, j + 5, k + 9, 5);
	world.setBlock(i + 3, j + 5, k + 10, 17);
	world.setBlockMetadata(i + 3, j + 5, k + 10, 1);
	world.setBlock(i + 3, j + 5, k + 11, 0);
	world.setBlock(i + 3, j + 5, k + 12, 0);
	world.setBlock(i + 3, j + 6, k + 0, 0);
	world.setBlock(i + 3, j + 6, k + 1, 0);
	world.setBlock(i + 3, j + 6, k + 2, 17);
	world.setBlockMetadata(i + 3, j + 6, k + 2, 1);
	world.setBlock(i + 3, j + 6, k + 3, 5);
	world.setBlock(i + 3, j + 6, k + 4, 5);
	world.setBlock(i + 3, j + 6, k + 5, 5);
	world.setBlock(i + 3, j + 6, k + 6, 5);
	world.setBlock(i + 3, j + 6, k + 7, 5);
	world.setBlock(i + 3, j + 6, k + 8, 5);
	world.setBlock(i + 3, j + 6, k + 9, 5);
	world.setBlock(i + 3, j + 6, k + 10, 17);
	world.setBlockMetadata(i + 3, j + 6, k + 10, 1);
	world.setBlock(i + 3, j + 6, k + 11, 0);
	world.setBlock(i + 3, j + 6, k + 12, 0);
	world.setBlock(i + 3, j + 7, k + 0, 0);
	world.setBlock(i + 3, j + 7, k + 1, 0);
	world.setBlock(i + 3, j + 7, k + 2, 17);
	world.setBlockMetadata(i + 3, j + 7, k + 2, 1);
	world.setBlock(i + 3, j + 7, k + 3, 5);
	world.setBlock(i + 3, j + 7, k + 4, 5);
	world.setBlock(i + 3, j + 7, k + 5, 5);
	world.setBlock(i + 3, j + 7, k + 6, 102);
	world.setBlock(i + 3, j + 7, k + 7, 5);
	world.setBlock(i + 3, j + 7, k + 8, 5);
	world.setBlock(i + 3, j + 7, k + 9, 102);
	world.setBlock(i + 3, j + 7, k + 10, 17);
	world.setBlockMetadata(i + 3, j + 7, k + 10, 1);
	world.setBlock(i + 3, j + 7, k + 11, 0);
	world.setBlock(i + 3, j + 7, k + 12, 0);
	world.setBlock(i + 3, j + 8, k + 0, 0);
	world.setBlock(i + 3, j + 8, k + 1, 0);
	world.setBlock(i + 3, j + 8, k + 2, 17);
	world.setBlockMetadata(i + 3, j + 8, k + 2, 1);
	world.setBlock(i + 3, j + 8, k + 3, 5);
	world.setBlock(i + 3, j + 8, k + 4, 5);
	world.setBlock(i + 3, j + 8, k + 5, 5);
	world.setBlock(i + 3, j + 8, k + 6, 102);
	world.setBlock(i + 3, j + 8, k + 7, 5);
	world.setBlock(i + 3, j + 8, k + 8, 5);
	world.setBlock(i + 3, j + 8, k + 9, 5);
	world.setBlock(i + 3, j + 8, k + 10, 53);
	world.setBlockMetadata(i + 3, j + 8, k + 10, 3);
	world.setBlock(i + 3, j + 8, k + 11, 0);
	world.setBlock(i + 3, j + 8, k + 12, 0);
	world.setBlock(i + 3, j + 9, k + 0, 0);
	world.setBlock(i + 3, j + 9, k + 1, 0);
	world.setBlock(i + 3, j + 9, k + 2, 17);
	world.setBlockMetadata(i + 3, j + 9, k + 2, 1);
	world.setBlock(i + 3, j + 9, k + 3, 5);
	world.setBlock(i + 3, j + 9, k + 4, 5);
	world.setBlock(i + 3, j + 9, k + 5, 5);
	world.setBlock(i + 3, j + 9, k + 6, 5);
	world.setBlock(i + 3, j + 9, k + 7, 5);
	world.setBlock(i + 3, j + 9, k + 8, 5);
	world.setBlock(i + 3, j + 9, k + 9, 53);
	world.setBlockMetadata(i + 3, j + 9, k + 9, 3);
	world.setBlock(i + 3, j + 9, k + 10, 0);
	world.setBlock(i + 3, j + 9, k + 11, 0);
	world.setBlock(i + 3, j + 9, k + 12, 0);
	world.setBlock(i + 3, j + 10, k + 0, 0);
	world.setBlock(i + 3, j + 10, k + 1, 0);
	world.setBlock(i + 3, j + 10, k + 2, 17);
	world.setBlockMetadata(i + 3, j + 10, k + 2, 1);
	world.setBlock(i + 3, j + 10, k + 3, 5);
	world.setBlock(i + 3, j + 10, k + 4, 5);
	world.setBlock(i + 3, j + 10, k + 5, 5);
	world.setBlock(i + 3, j + 10, k + 6, 5);
	world.setBlock(i + 3, j + 10, k + 7, 5);
	world.setBlock(i + 3, j + 10, k + 8, 53);
	world.setBlockMetadata(i + 3, j + 10, k + 8, 3);
	world.setBlock(i + 3, j + 10, k + 9, 0);
	world.setBlock(i + 3, j + 10, k + 10, 0);
	world.setBlock(i + 3, j + 10, k + 11, 0);
	world.setBlock(i + 3, j + 10, k + 12, 0);
	world.setBlock(i + 3, j + 11, k + 0, 0);
	world.setBlock(i + 3, j + 11, k + 1, 53);
	world.setBlockMetadata(i + 3, j + 11, k + 1, 2);
	world.setBlock(i + 3, j + 11, k + 2, 17);
	world.setBlockMetadata(i + 3, j + 11, k + 2, 1);
	world.setBlock(i + 3, j + 11, k + 3, 5);
	world.setBlock(i + 3, j + 11, k + 4, 5);
	world.setBlock(i + 3, j + 11, k + 5, 5);
	world.setBlock(i + 3, j + 11, k + 6, 5);
	world.setBlock(i + 3, j + 11, k + 7, 53);
	world.setBlockMetadata(i + 3, j + 11, k + 7, 3);
	world.setBlock(i + 3, j + 11, k + 8, 0);
	world.setBlock(i + 3, j + 11, k + 9, 0);
	world.setBlock(i + 3, j + 11, k + 10, 0);
	world.setBlock(i + 3, j + 11, k + 11, 0);
	world.setBlock(i + 3, j + 11, k + 12, 0);
	world.setBlock(i + 3, j + 12, k + 0, 0);
	world.setBlock(i + 3, j + 12, k + 1, 0);
	world.setBlock(i + 3, j + 12, k + 2, 53);
	world.setBlockMetadata(i + 3, j + 12, k + 2, 2);
	world.setBlock(i + 3, j + 12, k + 3, 5);
	world.setBlock(i + 3, j + 12, k + 4, 5);
	world.setBlock(i + 3, j + 12, k + 5, 5);
	world.setBlock(i + 3, j + 12, k + 6, 53);
	world.setBlockMetadata(i + 3, j + 12, k + 6, 3);
	world.setBlock(i + 3, j + 12, k + 7, 0);
	world.setBlock(i + 3, j + 12, k + 8, 0);
	world.setBlock(i + 3, j + 12, k + 9, 0);
	world.setBlock(i + 3, j + 12, k + 10, 0);
	world.setBlock(i + 3, j + 12, k + 11, 0);
	world.setBlock(i + 3, j + 12, k + 12, 0);
	world.setBlock(i + 3, j + 13, k + 0, 0);
	world.setBlock(i + 3, j + 13, k + 1, 0);
	world.setBlock(i + 3, j + 13, k + 2, 0);
	world.setBlock(i + 3, j + 13, k + 3, 53);
	world.setBlockMetadata(i + 3, j + 13, k + 3, 2);
	world.setBlock(i + 3, j + 13, k + 4, 5);
	world.setBlock(i + 3, j + 13, k + 5, 53);
	world.setBlockMetadata(i + 3, j + 13, k + 5, 3);
	world.setBlock(i + 3, j + 13, k + 6, 0);
	world.setBlock(i + 3, j + 13, k + 7, 0);
	world.setBlock(i + 3, j + 13, k + 8, 0);
	world.setBlock(i + 3, j + 13, k + 9, 0);
	world.setBlock(i + 3, j + 13, k + 10, 0);
	world.setBlock(i + 3, j + 13, k + 11, 0);
	world.setBlock(i + 3, j + 13, k + 12, 0);
	world.setBlock(i + 4, j + 0, k + 0, 3);
	world.setBlock(i + 4, j + 0, k + 1, 3);
	world.setBlock(i + 4, j + 0, k + 2, 3);
	world.setBlock(i + 4, j + 0, k + 3, 3);
	world.setBlock(i + 4, j + 0, k + 4, 3);
	world.setBlock(i + 4, j + 0, k + 5, 4);
	world.setBlock(i + 4, j + 0, k + 6, 0);
	world.setBlock(i + 4, j + 0, k + 7, 0);
	world.setBlock(i + 4, j + 0, k + 8, 0);
	world.setBlock(i + 4, j + 0, k + 9, 0);
	world.setBlock(i + 4, j + 0, k + 10, 4);
	world.setBlock(i + 4, j + 0, k + 11, 2);
	world.setBlock(i + 4, j + 0, k + 12, 2);
	world.setBlock(i + 4, j + 1, k + 0, 0);
	world.setBlock(i + 4, j + 1, k + 1, 0);
	world.setBlock(i + 4, j + 1, k + 2, 4);
	world.setBlock(i + 4, j + 1, k + 3, 4);
	world.setBlock(i + 4, j + 1, k + 4, 4);
	world.setBlock(i + 4, j + 1, k + 5, 4);
	world.setBlock(i + 4, j + 1, k + 6, 4);
	world.setBlock(i + 4, j + 1, k + 7, 4);
	world.setBlock(i + 4, j + 1, k + 8, 4);
	world.setBlock(i + 4, j + 1, k + 9, 4);
	world.setBlock(i + 4, j + 1, k + 10, 4);
	world.setBlock(i + 4, j + 1, k + 11, 0);
	world.setBlock(i + 4, j + 1, k + 12, 0);
	world.setBlock(i + 4, j + 2, k + 0, 0);
	world.setBlock(i + 4, j + 2, k + 1, 0);
	world.setBlock(i + 4, j + 2, k + 2, 5);
	world.setBlock(i + 4, j + 2, k + 3, 0);
	world.setBlock(i + 4, j + 2, k + 4, 0);
	world.setBlock(i + 4, j + 2, k + 5, 53);
	world.setBlockMetadata(i + 4, j + 2, k + 5, 2);
	world.setBlock(i + 4, j + 2, k + 6, 5);
	world.setBlock(i + 4, j + 2, k + 7, 5);
	world.setBlock(i + 4, j + 2, k + 8, 5);
	world.setBlock(i + 4, j + 2, k + 9, 5);
	world.setBlock(i + 4, j + 2, k + 10, 5);
	world.setBlock(i + 4, j + 2, k + 11, 0);
	world.setBlock(i + 4, j + 2, k + 12, 0);
	world.setBlock(i + 4, j + 3, k + 0, 0);
	world.setBlock(i + 4, j + 3, k + 1, 0);
	world.setBlock(i + 4, j + 3, k + 2, 5);
	world.setBlock(i + 4, j + 3, k + 3, 0);
	world.setBlock(i + 4, j + 3, k + 4, 0);
	world.setBlock(i + 4, j + 3, k + 5, 0);
	world.setBlock(i + 4, j + 3, k + 6, 53);
	world.setBlockMetadata(i + 4, j + 3, k + 6, 2);
	world.setBlock(i + 4, j + 3, k + 7, 5);
	world.setBlock(i + 4, j + 3, k + 8, 5);
	world.setBlock(i + 4, j + 3, k + 9, 5);
	world.setBlock(i + 4, j + 3, k + 10, 5);
	world.setBlock(i + 4, j + 3, k + 11, 0);
	world.setBlock(i + 4, j + 3, k + 12, 0);
	world.setBlock(i + 4, j + 4, k + 0, 0);
	world.setBlock(i + 4, j + 4, k + 1, 0);
	world.setBlock(i + 4, j + 4, k + 2, 5);
	world.setBlock(i + 4, j + 4, k + 3, 0);
	world.setBlock(i + 4, j + 4, k + 4, 0);
	world.setBlock(i + 4, j + 4, k + 6, 0);
	world.setBlock(i + 4, j + 4, k + 7, 53);
	world.setBlockMetadata(i + 4, j + 4, k + 7, 2);
	world.setBlock(i + 4, j + 4, k + 8, 5);
	world.setBlock(i + 4, j + 4, k + 9, 5);
	world.setBlock(i + 4, j + 4, k + 10, 5);
	world.setBlock(i + 4, j + 4, k + 11, 0);
	world.setBlock(i + 4, j + 4, k + 12, 0);
	world.setBlock(i + 4, j + 5, k + 0, 0);
	world.setBlock(i + 4, j + 5, k + 1, 0);
	world.setBlock(i + 4, j + 5, k + 2, 5);
	world.setBlock(i + 4, j + 5, k + 3, 5);
	world.setBlock(i + 4, j + 5, k + 4, 5);
	world.setBlock(i + 4, j + 5, k + 5, 0);
	world.setBlock(i + 4, j + 5, k + 6, 0);
	world.setBlock(i + 4, j + 5, k + 7, 0);
	world.setBlock(i + 4, j + 5, k + 8, 53);
	world.setBlockMetadata(i + 4, j + 5, k + 8, 2);
	world.setBlock(i + 4, j + 5, k + 9, 5);
	world.setBlock(i + 4, j + 5, k + 10, 5);
	world.setBlock(i + 4, j + 5, k + 11, 0);
	world.setBlock(i + 4, j + 5, k + 12, 0);
	world.setBlock(i + 4, j + 6, k + 0, 0);
	world.setBlock(i + 4, j + 6, k + 1, 0);
	world.setBlock(i + 4, j + 6, k + 2, 5);
	world.setBlock(i + 4, j + 6, k + 3, 0);
	world.setBlock(i + 4, j + 6, k + 4, 0);
	world.setBlock(i + 4, j + 6, k + 5, 5);
	world.setBlock(i + 4, j + 6, k + 6, 0);
	world.setBlock(i + 4, j + 6, k + 7, 0);
	world.setBlock(i + 4, j + 6, k + 8, 0);
	world.setBlock(i + 4, j + 6, k + 9, 0);
	world.setBlock(i + 4, j + 6, k + 10, 5);
	world.setBlock(i + 4, j + 6, k + 11, 0);
	world.setBlock(i + 4, j + 6, k + 12, 0);
	world.setBlock(i + 4, j + 7, k + 0, 0);
	world.setBlock(i + 4, j + 7, k + 1, 0);
	world.setBlock(i + 4, j + 7, k + 2, 5);
	world.setBlock(i + 4, j + 7, k + 3, 0);
	world.setBlock(i + 4, j + 7, k + 4, 0);
	world.setBlock(i + 4, j + 7, k + 5, 5);
	world.setBlock(i + 4, j + 7, k + 6, 0);
	world.setBlock(i + 4, j + 7, k + 7, 0);
	world.setBlock(i + 4, j + 7, k + 8, 0);
	world.setBlock(i + 4, j + 7, k + 9, 0);
	world.setBlock(i + 4, j + 7, k + 10, 5);
	world.setBlock(i + 4, j + 7, k + 11, 0);
	world.setBlock(i + 4, j + 7, k + 12, 0);
	world.setBlock(i + 4, j + 8, k + 0, 0);
	world.setBlock(i + 4, j + 8, k + 1, 0);
	world.setBlock(i + 4, j + 8, k + 2, 5);
	world.setBlock(i + 4, j + 8, k + 3, 0);
	world.setBlock(i + 4, j + 8, k + 4, 0);
	world.setBlock(i + 4, j + 8, k + 5, 5);
	world.setBlock(i + 4, j + 8, k + 6, 0);
	world.setBlock(i + 4, j + 8, k + 7, 0);
	world.setBlock(i + 4, j + 8, k + 8, 0);
	world.setBlock(i + 4, j + 8, k + 9, 0);
	world.setBlock(i + 4, j + 8, k + 10, 53);
	world.setBlockMetadata(i + 4, j + 8, k + 10, 3);
	world.setBlock(i + 4, j + 8, k + 11, 0);
	world.setBlock(i + 4, j + 8, k + 12, 0);
	world.setBlock(i + 4, j + 9, k + 0, 0);
	world.setBlock(i + 4, j + 9, k + 1, 0);
	world.setBlock(i + 4, j + 9, k + 2, 5);
	world.setBlock(i + 4, j + 9, k + 3, 0);
	world.setBlock(i + 4, j + 9, k + 4, 5);
	world.setBlock(i + 4, j + 9, k + 5, 5);
	world.setBlock(i + 4, j + 9, k + 6, 0);
	world.setBlock(i + 4, j + 9, k + 7, 0);
	world.setBlock(i + 4, j + 9, k + 8, 5);
	world.setBlock(i + 4, j + 9, k + 9, 53);
	world.setBlockMetadata(i + 4, j + 9, k + 9, 3);
	world.setBlock(i + 4, j + 9, k + 10, 0);
	world.setBlock(i + 4, j + 9, k + 11, 0);
	world.setBlock(i + 4, j + 9, k + 12, 0);
	world.setBlock(i + 4, j + 10, k + 0, 0);
	world.setBlock(i + 4, j + 10, k + 1, 0);
	world.setBlock(i + 4, j + 10, k + 2, 5);
	world.setBlock(i + 4, j + 10, k + 3, 0);
	world.setBlock(i + 4, j + 10, k + 4, 0);
	world.setBlock(i + 4, j + 10, k + 5, 0);
	world.setBlock(i + 4, j + 10, k + 6, 5);
	world.setBlock(i + 4, j + 10, k + 7, 5);
	world.setBlock(i + 4, j + 10, k + 8, 53);
	world.setBlockMetadata(i + 4, j + 10, k + 8, 3);
	world.setBlock(i + 4, j + 10, k + 9, 0);
	world.setBlock(i + 4, j + 10, k + 10, 0);
	world.setBlock(i + 4, j + 10, k + 11, 0);
	world.setBlock(i + 4, j + 10, k + 12, 0);
	world.setBlock(i + 4, j + 11, k + 0, 0);
	world.setBlock(i + 4, j + 11, k + 1, 53);
	world.setBlockMetadata(i + 4, j + 11, k + 1, 2);
	world.setBlock(i + 4, j + 11, k + 2, 5);
	world.setBlock(i + 4, j + 11, k + 3, 0);
	world.setBlock(i + 4, j + 11, k + 4, 0);
	world.setBlock(i + 4, j + 11, k + 5, 5);
	world.setBlock(i + 4, j + 11, k + 6, 5);
	world.setBlock(i + 4, j + 11, k + 7, 53);
	world.setBlockMetadata(i + 4, j + 11, k + 7, 3);
	world.setBlock(i + 4, j + 11, k + 8, 0);
	world.setBlock(i + 4, j + 11, k + 9, 0);
	world.setBlock(i + 4, j + 11, k + 10, 0);
	world.setBlock(i + 4, j + 11, k + 11, 0);
	world.setBlock(i + 4, j + 11, k + 12, 0);
	world.setBlock(i + 4, j + 12, k + 0, 0);
	world.setBlock(i + 4, j + 12, k + 1, 0);
	world.setBlock(i + 4, j + 12, k + 2, 53);
	world.setBlockMetadata(i + 4, j + 12, k + 2, 2);
	world.setBlock(i + 4, j + 12, k + 3, 5);
	world.setBlock(i + 4, j + 12, k + 4, 5);
	world.setBlock(i + 4, j + 12, k + 5, 5);
	world.setBlock(i + 4, j + 12, k + 6, 53);
	world.setBlockMetadata(i + 4, j + 12, k + 6, 3);
	world.setBlock(i + 4, j + 12, k + 7, 0);
	world.setBlock(i + 4, j + 12, k + 8, 0);
	world.setBlock(i + 4, j + 12, k + 9, 0);
	world.setBlock(i + 4, j + 12, k + 10, 0);
	world.setBlock(i + 4, j + 12, k + 11, 0);
	world.setBlock(i + 4, j + 12, k + 12, 0);
	world.setBlock(i + 4, j + 13, k + 0, 0);
	world.setBlock(i + 4, j + 13, k + 1, 0);
	world.setBlock(i + 4, j + 13, k + 2, 0);
	world.setBlock(i + 4, j + 13, k + 3, 53);
	world.setBlockMetadata(i + 4, j + 13, k + 3, 2);
	world.setBlock(i + 4, j + 13, k + 4, 5);
	world.setBlock(i + 4, j + 13, k + 5, 53);
	world.setBlockMetadata(i + 4, j + 13, k + 5, 3);
	world.setBlock(i + 4, j + 13, k + 6, 0);
	world.setBlock(i + 4, j + 13, k + 7, 0);
	world.setBlock(i + 4, j + 13, k + 8, 0);
	world.setBlock(i + 4, j + 13, k + 9, 0);
	world.setBlock(i + 4, j + 13, k + 10, 0);
	world.setBlock(i + 4, j + 13, k + 11, 0);
	world.setBlock(i + 4, j + 13, k + 12, 0);
	world.setBlock(i + 5, j + 0, k + 0, 3);
	world.setBlock(i + 5, j + 0, k + 1, 3);
	world.setBlock(i + 5, j + 0, k + 2, 3);
	world.setBlock(i + 5, j + 0, k + 3, 3);
	world.setBlock(i + 5, j + 0, k + 4, 3);
	world.setBlock(i + 5, j + 0, k + 5, 4);
	world.setBlock(i + 5, j + 0, k + 6, 0);
	world.setBlock(i + 5, j + 0, k + 7, 0);
	world.setBlock(i + 5, j + 0, k + 8, 0);
	world.setBlock(i + 5, j + 0, k + 9, 0);
	world.setBlock(i + 5, j + 0, k + 10, 4);
	world.setBlock(i + 5, j + 0, k + 11, 2);
	world.setBlock(i + 5, j + 0, k + 12, 2);
	world.setBlock(i + 5, j + 1, k + 0, 0);
	world.setBlock(i + 5, j + 1, k + 1, 0);
	world.setBlock(i + 5, j + 1, k + 2, 4);
	world.setBlock(i + 5, j + 1, k + 3, 4);
	world.setBlock(i + 5, j + 1, k + 4, 4);
	world.setBlock(i + 5, j + 1, k + 5, 4);
	world.setBlock(i + 5, j + 1, k + 6, 4);
	world.setBlock(i + 5, j + 1, k + 7, 4);
	world.setBlock(i + 5, j + 1, k + 8, 4);
	world.setBlock(i + 5, j + 1, k + 9, 4);
	world.setBlock(i + 5, j + 1, k + 10, 4);
	world.setBlock(i + 5, j + 1, k + 11, 0);
	world.setBlock(i + 5, j + 1, k + 12, 0);
	world.setBlock(i + 5, j + 2, k + 0, 0);
	world.setBlock(i + 5, j + 2, k + 1, 0);
	world.setBlock(i + 5, j + 2, k + 2, 5);
	world.setBlock(i + 5, j + 2, k + 3, 0);
	world.setBlock(i + 5, j + 2, k + 4, 0);
	world.setBlock(i + 5, j + 2, k + 5, 0);
	world.setBlock(i + 5, j + 2, k + 6, 0);
	world.setBlock(i + 5, j + 2, k + 7, Block.chest.blockID);
	TileEntityChest tileentitychest = (TileEntityChest)world.getBlockTileEntity(i + 5, j + 2, k + 7);
    if(tileentitychest != null && tileentitychest.getSizeInventory() > 0)
    {
                  ItemStack itemstack = new ItemStack(mod_Desserts.BlockMelonCake, 3);
                  tileentitychest.setInventorySlotContents(0, itemstack);
                  ItemStack itemstack1 = new ItemStack(Item.diamond, 17);
                  tileentitychest.setInventorySlotContents(1, itemstack1);
                  ItemStack itemstack2 = new ItemStack(Item.coal, 20);
                  tileentitychest.setInventorySlotContents(2, itemstack2);
                  ItemStack itemstack3 = new ItemStack(Item.shears, 3);
                  tileentitychest.setInventorySlotContents(2, itemstack3);
                  ItemStack itemstack4 = new ItemStack(mod_Desserts.sword, 2);
                  tileentitychest.setInventorySlotContents(2, itemstack4);
    }
	world.setBlockMetadata(i + 5, j + 2, k + 7, 5);
	world.setBlock(i + 5, j + 2, k + 8, 58);
	world.setBlock(i + 5, j + 2, k + 9, 61);
	TileEntityFurnace tileentityfurnace = (TileEntityFurnace)world.getBlockTileEntity(i + 5, j + 2, k + 9);
    if(tileentityfurnace != null && tileentityfurnace.getSizeInventory() > 0)
    {
                
                  ItemStack itemstack6 = new ItemStack(Item.coal, 20);
                  tileentityfurnace.setInventorySlotContents(2, itemstack6);
                
    }
	world.setBlockMetadata(i + 5, j + 2, k + 9, 5);
	world.setBlock(i + 5, j + 2, k + 10, 5);
	world.setBlock(i + 5, j + 2, k + 11, 0);
	world.setBlock(i + 5, j + 2, k + 12, 0);
	world.setBlock(i + 5, j + 3, k + 0, 0);
	world.setBlock(i + 5, j + 3, k + 1, 0);
	world.setBlock(i + 5, j + 3, k + 2, 5);
	world.setBlock(i + 5, j + 3, k + 3, 0);
	world.setBlock(i + 5, j + 3, k + 4, 0);
	world.setBlock(i + 5, j + 3, k + 5, 0);
	world.setBlock(i + 5, j + 3, k + 6, 0);
	world.setBlock(i + 5, j + 3, k + 7, 0);
	world.setBlock(i + 5, j + 3, k + 8, 0);
	world.setBlock(i + 5, j + 3, k + 9, 61);
	world.setBlockMetadata(i + 5, j + 3, k + 9, 5);
	world.setBlock(i + 5, j + 3, k + 10, 5);
	world.setBlock(i + 5, j + 3, k + 11, 0);
	world.setBlock(i + 5, j + 3, k + 12, 0);
	world.setBlock(i + 5, j + 4, k + 0, 0);
	world.setBlock(i + 5, j + 4, k + 1, 0);
	world.setBlock(i + 5, j + 4, k + 2, 5);
	world.setBlock(i + 5, j + 4, k + 3, 0);
	world.setBlock(i + 5, j + 4, k + 4, 0);
	world.setBlock(i + 5, j + 4, k + 5, 0);
	world.setBlock(i + 5, j + 4, k + 6, 0);
	world.setBlock(i + 5, j + 4, k + 7, 0);
	world.setBlock(i + 5, j + 4, k + 8, 0);
	world.setBlock(i + 5, j + 4, k + 9, 0);
	world.setBlock(i + 5, j + 4, k + 10, 5);
	world.setBlock(i + 5, j + 4, k + 11, 0);
	world.setBlock(i + 5, j + 4, k + 12, 0);
	world.setBlock(i + 5, j + 5, k + 0, 0);
	world.setBlock(i + 5, j + 5, k + 1, 0);
	world.setBlock(i + 5, j + 5, k + 2, 5);
	world.setBlock(i + 5, j + 5, k + 3, 5);
	world.setBlock(i + 5, j + 5, k + 4, 5);
	world.setBlock(i + 5, j + 5, k + 5, 5);
	world.setBlock(i + 5, j + 5, k + 6, 5);
	world.setBlock(i + 5, j + 5, k + 7, 5);
	world.setBlock(i + 5, j + 5, k + 8, 5);
	world.setBlock(i + 5, j + 5, k + 9, 5);
	world.setBlock(i + 5, j + 5, k + 10, 5);
	world.setBlock(i + 5, j + 5, k + 11, 0);
	world.setBlock(i + 5, j + 5, k + 12, 0);
	world.setBlock(i + 5, j + 6, k + 0, 0);
	world.setBlock(i + 5, j + 6, k + 1, 0);
	world.setBlock(i + 5, j + 6, k + 2, 5);
	world.setBlock(i + 5, j + 6, k + 3, 0);
	world.setBlock(i + 5, j + 6, k + 4, 0);
	world.setBlock(i + 5, j + 6, k + 5, 5);
	world.setBlock(i + 5, j + 6, k + 6, 85);
	world.setBlock(i + 5, j + 6, k + 7, 85);
	world.setBlock(i + 5, j + 6, k + 8, 85);
	world.setBlock(i + 5, j + 6, k + 9, 0);
	world.setBlock(i + 5, j + 6, k + 10, 5);
	world.setBlock(i + 5, j + 6, k + 11, 0);
	world.setBlock(i + 5, j + 6, k + 12, 0);
	world.setBlock(i + 5, j + 7, k + 0, 0);
	world.setBlock(i + 5, j + 7, k + 1, 0);
	world.setBlock(i + 5, j + 7, k + 2, 5);
	world.setBlock(i + 5, j + 7, k + 3, 0);
	world.setBlock(i + 5, j + 7, k + 4, 0);
	world.setBlock(i + 5, j + 7, k + 5, 5);
	world.setBlock(i + 5, j + 7, k + 6, 0);
	world.setBlock(i + 5, j + 7, k + 7, 0);
	world.setBlock(i + 5, j + 7, k + 8, 0);
	world.setBlock(i + 5, j + 7, k + 9, 0);
	world.setBlock(i + 5, j + 7, k + 10, 5);
	world.setBlock(i + 5, j + 7, k + 11, 0);
	world.setBlock(i + 5, j + 7, k + 12, 0);
	world.setBlock(i + 5, j + 8, k + 0, 0);
	world.setBlock(i + 5, j + 8, k + 1, 0);
	world.setBlock(i + 5, j + 8, k + 2, 5);
	world.setBlock(i + 5, j + 8, k + 3, 0);
	world.setBlock(i + 5, j + 8, k + 4, 0);
	world.setBlock(i + 5, j + 8, k + 5, 5);
	world.setBlock(i + 5, j + 8, k + 6, 0);
	world.setBlock(i + 5, j + 8, k + 7, 0);
	world.setBlock(i + 5, j + 8, k + 8, 0);
	world.setBlock(i + 5, j + 8, k + 9, 0);
	world.setBlock(i + 5, j + 8, k + 10, 53);
	world.setBlockMetadata(i + 5, j + 8, k + 10, 3);
	world.setBlock(i + 5, j + 8, k + 11, 0);
	world.setBlock(i + 5, j + 8, k + 12, 0);
	world.setBlock(i + 5, j + 9, k + 0, 0);
	world.setBlock(i + 5, j + 9, k + 1, 0);
	world.setBlock(i + 5, j + 9, k + 2, 5);
	world.setBlock(i + 5, j + 9, k + 3, 5);
	world.setBlock(i + 5, j + 9, k + 4, 5);
	world.setBlock(i + 5, j + 9, k + 5, 5);
	world.setBlock(i + 5, j + 9, k + 6, 0);
	world.setBlock(i + 5, j + 9, k + 7, 0);
	world.setBlock(i + 5, j + 9, k + 8, 5);
	world.setBlock(i + 5, j + 9, k + 9, 53);
	world.setBlockMetadata(i + 5, j + 9, k + 9, 3);
	world.setBlock(i + 5, j + 9, k + 10, 0);
	world.setBlock(i + 5, j + 9, k + 11, 0);
	world.setBlock(i + 5, j + 9, k + 12, 0);
	world.setBlock(i + 5, j + 10, k + 0, 0);
	world.setBlock(i + 5, j + 10, k + 1, 0);
	world.setBlock(i + 5, j + 10, k + 2, 5);
	world.setBlock(i + 5, j + 10, k + 3, 0);
	world.setBlock(i + 5, j + 10, k + 4, 0);
	world.setBlock(i + 5, j + 10, k + 5, 0);
	world.setBlock(i + 5, j + 10, k + 6, 5);
	world.setBlock(i + 5, j + 10, k + 7, 5);
	world.setBlock(i + 5, j + 10, k + 8, 53);
	world.setBlockMetadata(i + 5, j + 10, k + 8, 3);
	world.setBlock(i + 5, j + 10, k + 9, 0);
	world.setBlock(i + 5, j + 10, k + 10, 0);
	world.setBlock(i + 5, j + 10, k + 11, 0);
	world.setBlock(i + 5, j + 10, k + 12, 0);
	world.setBlock(i + 5, j + 11, k + 0, 0);
	world.setBlock(i + 5, j + 11, k + 1, 53);
	world.setBlockMetadata(i + 5, j + 11, k + 1, 2);
	world.setBlock(i + 5, j + 11, k + 2, 5);
	world.setBlock(i + 5, j + 11, k + 3, 0);
	world.setBlock(i + 5, j + 11, k + 4, 0);
	world.setBlock(i + 5, j + 11, k + 5, 5);
	world.setBlock(i + 5, j + 11, k + 6, 5);
	world.setBlock(i + 5, j + 11, k + 7, 53);
	world.setBlockMetadata(i + 5, j + 11, k + 7, 3);
	world.setBlock(i + 5, j + 11, k + 8, 0);
	world.setBlock(i + 5, j + 11, k + 9, 0);
	world.setBlock(i + 5, j + 11, k + 10, 0);
	world.setBlock(i + 5, j + 11, k + 11, 0);
	world.setBlock(i + 5, j + 11, k + 12, 0);
	world.setBlock(i + 5, j + 12, k + 0, 0);
	world.setBlock(i + 5, j + 12, k + 1, 0);
	world.setBlock(i + 5, j + 12, k + 2, 53);
	world.setBlockMetadata(i + 5, j + 12, k + 2, 2);
	world.setBlock(i + 5, j + 12, k + 3, 5);
	world.setBlock(i + 5, j + 12, k + 4, 5);
	world.setBlock(i + 5, j + 12, k + 5, 5);
	world.setBlock(i + 5, j + 12, k + 6, 53);
	world.setBlockMetadata(i + 5, j + 12, k + 6, 3);
	world.setBlock(i + 5, j + 12, k + 7, 0);
	world.setBlock(i + 5, j + 12, k + 8, 0);
	world.setBlock(i + 5, j + 12, k + 9, 0);
	world.setBlock(i + 5, j + 12, k + 10, 0);
	world.setBlock(i + 5, j + 12, k + 11, 0);
	world.setBlock(i + 5, j + 12, k + 12, 0);
	world.setBlock(i + 5, j + 13, k + 0, 0);
	world.setBlock(i + 5, j + 13, k + 1, 0);
	world.setBlock(i + 5, j + 13, k + 2, 0);
	world.setBlock(i + 5, j + 13, k + 3, 53);
	world.setBlockMetadata(i + 5, j + 13, k + 3, 2);
	world.setBlock(i + 5, j + 13, k + 4, 5);
	world.setBlock(i + 5, j + 13, k + 5, 53);
	world.setBlockMetadata(i + 5, j + 13, k + 5, 3);
	world.setBlock(i + 5, j + 13, k + 6, 0);
	world.setBlock(i + 5, j + 13, k + 7, 0);
	world.setBlock(i + 5, j + 13, k + 8, 0);
	world.setBlock(i + 5, j + 13, k + 9, 0);
	world.setBlock(i + 5, j + 13, k + 10, 0);
	world.setBlock(i + 5, j + 13, k + 11, 0);
	world.setBlock(i + 5, j + 13, k + 12, 0);
	world.setBlock(i + 6, j + 0, k + 0, 3);
	world.setBlock(i + 6, j + 0, k + 1, 2);
	world.setBlock(i + 6, j + 0, k + 2, 3);
	world.setBlock(i + 6, j + 0, k + 3, 3);
	world.setBlock(i + 6, j + 0, k + 4, 3);
	world.setBlock(i + 6, j + 0, k + 5, 4);
	world.setBlock(i + 6, j + 0, k + 6, 0);
	world.setBlock(i + 6, j + 0, k + 7, 0);
	world.setBlock(i + 6, j + 0, k + 8, 0);
	world.setBlock(i + 6, j + 0, k + 9, 0);
	world.setBlock(i + 6, j + 0, k + 10, 4);
	world.setBlock(i + 6, j + 0, k + 11, 3);
	world.setBlock(i + 6, j + 0, k + 12, 2);
	world.setBlock(i + 6, j + 1, k + 0, 0);
	world.setBlock(i + 6, j + 1, k + 1, 0);
	world.setBlock(i + 6, j + 1, k + 2, 4);
	world.setBlock(i + 6, j + 1, k + 3, 4);
	world.setBlock(i + 6, j + 1, k + 4, 4);
	world.setBlock(i + 6, j + 1, k + 5, 4);
	world.setBlock(i + 6, j + 1, k + 6, 4);
	world.setBlock(i + 6, j + 1, k + 7, 4);
	world.setBlock(i + 6, j + 1, k + 8, 4);
	world.setBlock(i + 6, j + 1, k + 9, 4);
	world.setBlock(i + 6, j + 1, k + 10, 4);
	world.setBlock(i + 6, j + 1, k + 11, 4);
	world.setBlock(i + 6, j + 1, k + 12, 0);
	world.setBlock(i + 6, j + 2, k + 0, 0);
	world.setBlock(i + 6, j + 2, k + 1, 0);
	world.setBlock(i + 6, j + 2, k + 2, 5);
	world.setBlock(i + 6, j + 2, k + 3, 0);
	world.setBlock(i + 6, j + 2, k + 4, 0);
	world.setBlock(i + 6, j + 2, k + 5, 0);
	world.setBlock(i + 6, j + 2, k + 6, 0);
	world.setBlock(i + 6, j + 2, k + 7, 0);
	world.setBlock(i + 6, j + 2, k + 8, 0);
	world.setBlock(i + 6, j + 2, k + 9, 0);
	world.setBlock(i + 6, j + 2, k + 10, 4);
	world.setBlock(i + 6, j + 2, k + 11, 4);
	world.setBlock(i + 6, j + 2, k + 12, 0);
	world.setBlock(i + 6, j + 3, k + 0, 0);
	world.setBlock(i + 6, j + 3, k + 1, 0);
	world.setBlock(i + 6, j + 3, k + 2, 102);
	world.setBlock(i + 6, j + 3, k + 3, 0);
	world.setBlock(i + 6, j + 3, k + 4, 0);
	world.setBlock(i + 6, j + 3, k + 5, 0);
	world.setBlock(i + 6, j + 3, k + 6, 0);
	world.setBlock(i + 6, j + 3, k + 7, 0);
	world.setBlock(i + 6, j + 3, k + 8, 0);
	world.setBlock(i + 6, j + 3, k + 9, 0);
	world.setBlock(i + 6, j + 3, k + 10, 4);
	world.setBlock(i + 6, j + 3, k + 11, 4);
	world.setBlock(i + 6, j + 3, k + 12, 0);
	world.setBlock(i + 6, j + 4, k + 0, 0);
	world.setBlock(i + 6, j + 4, k + 1, 0);
	world.setBlock(i + 6, j + 4, k + 2, 102);
	world.setBlock(i + 6, j + 4, k + 3, 0);
	world.setBlock(i + 6, j + 4, k + 4, 0);
	world.setBlock(i + 6, j + 4, k + 5, 0);
	world.setBlock(i + 6, j + 4, k + 6, 0);
	world.setBlock(i + 6, j + 4, k + 7, 0);
	world.setBlock(i + 6, j + 4, k + 8, 0);
	world.setBlock(i + 6, j + 4, k + 9, 0);
	world.setBlock(i + 6, j + 4, k + 10, 4);
	world.setBlock(i + 6, j + 4, k + 11, 4);
	world.setBlock(i + 6, j + 4, k + 12, 0);
	world.setBlock(i + 6, j + 5, k + 0, 0);
	world.setBlock(i + 6, j + 5, k + 1, 0);
	world.setBlock(i + 6, j + 5, k + 2, 5);
	world.setBlock(i + 6, j + 5, k + 3, 5);
	world.setBlock(i + 6, j + 5, k + 4, 5);
	world.setBlock(i + 6, j + 5, k + 5, 5);
	world.setBlock(i + 6, j + 5, k + 6, 5);
	world.setBlock(i + 6, j + 5, k + 7, 5);
	world.setBlock(i + 6, j + 5, k + 8, 5);
	world.setBlock(i + 6, j + 5, k + 9, 5);
	world.setBlock(i + 6, j + 5, k + 10, 5);
	world.setBlock(i + 6, j + 5, k + 11, 4);
	world.setBlock(i + 6, j + 5, k + 12, 0);
	world.setBlock(i + 6, j + 6, k + 0, 0);
	world.setBlock(i + 6, j + 6, k + 1, 0);
	world.setBlock(i + 6, j + 6, k + 2, 5);
	world.setBlock(i + 6, j + 6, k + 3, 0);
	world.setBlock(i + 6, j + 6, k + 4, 0);
	world.setBlock(i + 6, j + 6, k + 5, 5);
	world.setBlock(i + 6, j + 6, k + 6, 0);
	world.setBlock(i + 6, j + 6, k + 7, 0);
	world.setBlock(i + 6, j + 6, k + 8, 0);
	world.setBlock(i + 6, j + 6, k + 9, 0);
	world.setBlock(i + 6, j + 6, k + 10, 5);
	world.setBlock(i + 6, j + 6, k + 11, 4);
	world.setBlock(i + 6, j + 6, k + 12, 0);
	world.setBlock(i + 6, j + 7, k + 0, 0);
	world.setBlock(i + 6, j + 7, k + 1, 0);
	world.setBlock(i + 6, j + 7, k + 2, 102);
	world.setBlock(i + 6, j + 7, k + 3, 0);
	world.setBlock(i + 6, j + 7, k + 5, 5);
	world.setBlock(i + 6, j + 7, k + 6, 0);
	world.setBlock(i + 6, j + 7, k + 7, 0);
	world.setBlock(i + 6, j + 7, k + 8, 0);
	world.setBlock(i + 6, j + 7, k + 9, 0);
	world.setBlock(i + 6, j + 7, k + 10, 5);
	world.setBlock(i + 6, j + 7, k + 11, 4);
	world.setBlock(i + 6, j + 7, k + 12, 0);
	world.setBlock(i + 6, j + 8, k + 0, 0);
	world.setBlock(i + 6, j + 8, k + 1, 0);
	world.setBlock(i + 6, j + 8, k + 2, 102);
	world.setBlock(i + 6, j + 8, k + 3, 0);
	world.setBlock(i + 6, j + 8, k + 4, 0);
	world.setBlock(i + 6, j + 8, k + 5, 5);
	world.setBlock(i + 6, j + 8, k + 6, 0);
	world.setBlock(i + 6, j + 8, k + 7, 0);
	world.setBlock(i + 6, j + 8, k + 8, 0);
	world.setBlock(i + 6, j + 8, k + 9, 0);
	world.setBlock(i + 6, j + 8, k + 10, 53);
	world.setBlockMetadata(i + 6, j + 8, k + 10, 3);
	world.setBlock(i + 6, j + 8, k + 11, 4);
	world.setBlock(i + 6, j + 8, k + 12, 0);
	world.setBlock(i + 6, j + 9, k + 0, 0);
	world.setBlock(i + 6, j + 9, k + 1, 0);
	world.setBlock(i + 6, j + 9, k + 2, 5);
	world.setBlock(i + 6, j + 9, k + 3, 5);
	world.setBlock(i + 6, j + 9, k + 4, 5);
	world.setBlock(i + 6, j + 9, k + 5, 5);
	world.setBlock(i + 6, j + 9, k + 6, 0);
	world.setBlock(i + 6, j + 9, k + 7, 0);
	world.setBlock(i + 6, j + 9, k + 8, 5);
	world.setBlock(i + 6, j + 9, k + 9, 53);
	world.setBlockMetadata(i + 6, j + 9, k + 9, 3);
	world.setBlock(i + 6, j + 9, k + 10, 0);
	world.setBlock(i + 6, j + 9, k + 11, 4);
	world.setBlock(i + 6, j + 9, k + 12, 0);
	world.setBlock(i + 6, j + 10, k + 0, 0);
	world.setBlock(i + 6, j + 10, k + 1, 0);
	world.setBlock(i + 6, j + 10, k + 2, 5);
	world.setBlock(i + 6, j + 10, k + 3, 0);
	world.setBlock(i + 6, j + 10, k + 4, 0);
	world.setBlock(i + 6, j + 10, k + 5, 0);
	world.setBlock(i + 6, j + 10, k + 6, 5);
	world.setBlock(i + 6, j + 10, k + 7, 5);
	world.setBlock(i + 6, j + 10, k + 8, 53);
	world.setBlockMetadata(i + 6, j + 10, k + 8, 3);
	world.setBlock(i + 6, j + 10, k + 9, 0);
	world.setBlock(i + 6, j + 10, k + 10, 0);
	world.setBlock(i + 6, j + 10, k + 11, 4);
	world.setBlock(i + 6, j + 10, k + 12, 0);
	world.setBlock(i + 6, j + 11, k + 0, 0);
	world.setBlock(i + 6, j + 11, k + 1, 53);
	world.setBlockMetadata(i + 6, j + 11, k + 1, 2);
	world.setBlock(i + 6, j + 11, k + 2, 5);
	world.setBlock(i + 6, j + 11, k + 3, 0);
	world.setBlock(i + 6, j + 11, k + 4, 0);
	world.setBlock(i + 6, j + 11, k + 5, 5);
	world.setBlock(i + 6, j + 11, k + 6, 5);
	world.setBlock(i + 6, j + 11, k + 7, 53);
	world.setBlockMetadata(i + 6, j + 11, k + 7, 3);
	world.setBlock(i + 6, j + 11, k + 8, 0);
	world.setBlock(i + 6, j + 11, k + 9, 0);
	world.setBlock(i + 6, j + 11, k + 10, 0);
	world.setBlock(i + 6, j + 11, k + 11, 85);
	world.setBlock(i + 6, j + 11, k + 12, 0);
	world.setBlock(i + 6, j + 12, k + 0, 0);
	world.setBlock(i + 6, j + 12, k + 1, 0);
	world.setBlock(i + 6, j + 12, k + 2, 53);
	world.setBlockMetadata(i + 6, j + 12, k + 2, 2);
	world.setBlock(i + 6, j + 12, k + 3, 5);
	world.setBlock(i + 6, j + 12, k + 4, 5);
	world.setBlock(i + 6, j + 12, k + 5, 5);
	world.setBlock(i + 6, j + 12, k + 6, 53);
	world.setBlockMetadata(i + 6, j + 12, k + 6, 3);
	world.setBlock(i + 6, j + 12, k + 7, 0);
	world.setBlock(i + 6, j + 12, k + 8, 0);
	world.setBlock(i + 6, j + 12, k + 9, 0);
	world.setBlock(i + 6, j + 12, k + 10, 0);
	world.setBlock(i + 6, j + 12, k + 11, 4);
	world.setBlock(i + 6, j + 12, k + 12, 0);
	world.setBlock(i + 6, j + 13, k + 0, 0);
	world.setBlock(i + 6, j + 13, k + 1, 0);
	world.setBlock(i + 6, j + 13, k + 2, 0);
	world.setBlock(i + 6, j + 13, k + 3, 53);
	world.setBlockMetadata(i + 6, j + 13, k + 3, 2);
	world.setBlock(i + 6, j + 13, k + 4, 5);
	world.setBlock(i + 6, j + 13, k + 5, 53);
	world.setBlockMetadata(i + 6, j + 13, k + 5, 3);
	world.setBlock(i + 6, j + 13, k + 6, 0);
	world.setBlock(i + 6, j + 13, k + 7, 0);
	world.setBlock(i + 6, j + 13, k + 8, 0);
	world.setBlock(i + 6, j + 13, k + 9, 0);
	world.setBlock(i + 6, j + 13, k + 10, 0);
	world.setBlock(i + 6, j + 13, k + 11, 0);
	world.setBlock(i + 6, j + 13, k + 12, 0);
	world.setBlock(i + 7, j + 0, k + 0, 3);
	world.setBlock(i + 7, j + 0, k + 1, 2);
	world.setBlock(i + 7, j + 0, k + 2, 3);
	world.setBlock(i + 7, j + 0, k + 3, 3);
	world.setBlock(i + 7, j + 0, k + 4, 3);
	world.setBlock(i + 7, j + 0, k + 5, 4);
	world.setBlock(i + 7, j + 0, k + 6, 0);
	world.setBlock(i + 7, j + 0, k + 7, 0);
	world.setBlock(i + 7, j + 0, k + 8, 0);
	world.setBlock(i + 7, j + 0, k + 9, 0);
	world.setBlock(i + 7, j + 0, k + 10, 4);
	world.setBlock(i + 7, j + 0, k + 11, 3);
	world.setBlock(i + 7, j + 0, k + 12, 3);
	world.setBlock(i + 7, j + 1, k + 0, 0);
	world.setBlock(i + 7, j + 1, k + 1, 0);
	world.setBlock(i + 7, j + 1, k + 2, 4);
	world.setBlock(i + 7, j + 1, k + 3, 4);
	world.setBlock(i + 7, j + 1, k + 4, 4);
	world.setBlock(i + 7, j + 1, k + 5, 4);
	world.setBlock(i + 7, j + 1, k + 6, 4);
	world.setBlock(i + 7, j + 1, k + 7, 4);
	world.setBlock(i + 7, j + 1, k + 8, 4);
	world.setBlock(i + 7, j + 1, k + 9, 4);
	world.setBlock(i + 7, j + 1, k + 10, 4);
	world.setBlock(i + 7, j + 1, k + 11, 87);
	world.setBlock(i + 7, j + 1, k + 12, 4);
	world.setBlock(i + 7, j + 2, k + 0, 0);
	world.setBlock(i + 7, j + 2, k + 1, 0);
	world.setBlock(i + 7, j + 2, k + 2, 5);
	world.setBlock(i + 7, j + 2, k + 3, 0);
	world.setBlock(i + 7, j + 2, k + 4, 0);
	world.setBlock(i + 7, j + 2, k + 5, 0);
	world.setBlock(i + 7, j + 2, k + 6, 0);
	world.setBlock(i + 7, j + 2, k + 7, 0);
	world.setBlock(i + 7, j + 2, k + 8, 0);
	world.setBlock(i + 7, j + 2, k + 9, 0);
	world.setBlock(i + 7, j + 2, k + 10, 0);
	world.setBlock(i + 7, j + 2, k + 11, 51);
	world.setBlockMetadata(i + 7, j + 2, k + 11, 15);
	world.setBlock(i + 7, j + 2, k + 12, 4);
	world.setBlock(i + 7, j + 3, k + 0, 0);
	world.setBlock(i + 7, j + 3, k + 1, 0);
	world.setBlock(i + 7, j + 3, k + 2, 102);
	world.setBlock(i + 7, j + 3, k + 3, 0);
	world.setBlock(i + 7, j + 3, k + 4, 0);
	world.setBlock(i + 7, j + 3, k + 5, 0);
	world.setBlock(i + 7, j + 3, k + 6, 0);
	world.setBlock(i + 7, j + 3, k + 7, 0);
	world.setBlock(i + 7, j + 3, k + 8, 0);
	world.setBlock(i + 7, j + 3, k + 9, 0);
	world.setBlock(i + 7, j + 3, k + 10, 0);
	world.setBlock(i + 7, j + 3, k + 11, 0);
	world.setBlock(i + 7, j + 3, k + 12, 4);
	world.setBlock(i + 7, j + 4, k + 0, 0);
	world.setBlock(i + 7, j + 4, k + 1, 0);
	world.setBlock(i + 7, j + 4, k + 2, 102);
	world.setBlock(i + 7, j + 4, k + 3, 0);
	world.setBlock(i + 7, j + 4, k + 4, 0);
	world.setBlock(i + 7, j + 4, k + 5, 0);
	world.setBlock(i + 7, j + 4, k + 6, 0);
	world.setBlock(i + 7, j + 4, k + 7, 0);
	world.setBlock(i + 7, j + 4, k + 8, 0);
	world.setBlock(i + 7, j + 4, k + 9, 0);
	world.setBlock(i + 7, j + 4, k + 10, 4);
	world.setBlock(i + 7, j + 4, k + 11, 0);
	world.setBlock(i + 7, j + 4, k + 12, 4);
	world.setBlock(i + 7, j + 5, k + 0, 0);
	world.setBlock(i + 7, j + 5, k + 1, 0);
	world.setBlock(i + 7, j + 5, k + 2, 5);
	world.setBlock(i + 7, j + 5, k + 3, 5);
	world.setBlock(i + 7, j + 5, k + 4, 5);
	world.setBlock(i + 7, j + 5, k + 5, 5);
	world.setBlock(i + 7, j + 5, k + 6, 5);
	world.setBlock(i + 7, j + 5, k + 7, 5);
	world.setBlock(i + 7, j + 5, k + 8, 5);
	world.setBlock(i + 7, j + 5, k + 9, 5);
	world.setBlock(i + 7, j + 5, k + 10, 4);
	world.setBlock(i + 7, j + 5, k + 11, 0);
	world.setBlock(i + 7, j + 5, k + 12, 4);
	world.setBlock(i + 7, j + 6, k + 0, 0);
	world.setBlock(i + 7, j + 6, k + 1, 0);
	world.setBlock(i + 7, j + 6, k + 2, 5);
	world.setBlock(i + 7, j + 6, k + 3, 0);
	world.setBlock(i + 7, j + 6, k + 4, 0);
	world.setBlock(i + 7, j + 6, k + 6, 0);
	world.setBlock(i + 7, j + 6, k + 7, 0);
	world.setBlock(i + 7, j + 6, k + 8, 0);
	world.setBlock(i + 7, j + 6, k + 9, 0);
	world.setBlock(i + 7, j + 6, k + 10, 4);
	world.setBlock(i + 7, j + 6, k + 11, 0);
	world.setBlock(i + 7, j + 6, k + 12, 4);
	world.setBlock(i + 7, j + 7, k + 0, 0);
	world.setBlock(i + 7, j + 7, k + 1, 0);
	world.setBlock(i + 7, j + 7, k + 2, 102);
	world.setBlock(i + 7, j + 7, k + 3, 0);
	world.setBlock(i + 7, j + 7, k + 4, 0);
	world.setBlock(i + 7, j + 7, k + 6, 0);
	world.setBlock(i + 7, j + 7, k + 7, 0);
	world.setBlock(i + 7, j + 7, k + 8, 0);
	world.setBlock(i + 7, j + 7, k + 9, 0);
	world.setBlock(i + 7, j + 7, k + 10, 4);
	world.setBlock(i + 7, j + 7, k + 11, 0);
	world.setBlock(i + 7, j + 7, k + 12, 4);
	world.setBlock(i + 7, j + 8, k + 0, 0);
	world.setBlock(i + 7, j + 8, k + 1, 0);
	world.setBlock(i + 7, j + 8, k + 2, 102);
	world.setBlock(i + 7, j + 8, k + 3, 0);
	world.setBlock(i + 7, j + 8, k + 4, 0);
	world.setBlock(i + 7, j + 8, k + 5, 5);
	world.setBlock(i + 7, j + 8, k + 6, 0);
	world.setBlock(i + 7, j + 8, k + 7, 0);
	world.setBlock(i + 7, j + 8, k + 8, 0);
	world.setBlock(i + 7, j + 8, k + 9, 0);
	world.setBlock(i + 7, j + 8, k + 10, 4);
	world.setBlock(i + 7, j + 8, k + 11, 0);
	world.setBlock(i + 7, j + 8, k + 12, 4);
	world.setBlock(i + 7, j + 9, k + 0, 0);
	world.setBlock(i + 7, j + 9, k + 1, 0);
	world.setBlock(i + 7, j + 9, k + 2, 5);
	world.setBlock(i + 7, j + 9, k + 3, 5);
	world.setBlock(i + 7, j + 9, k + 4, 5);
	world.setBlock(i + 7, j + 9, k + 5, 5);
	world.setBlock(i + 7, j + 9, k + 6, 0);
	world.setBlock(i + 7, j + 9, k + 7, 0);
	world.setBlock(i + 7, j + 9, k + 8, 5);
	world.setBlock(i + 7, j + 9, k + 9, 53);
	world.setBlockMetadata(i + 7, j + 9, k + 9, 3);
	world.setBlock(i + 7, j + 9, k + 10, 4);
	world.setBlock(i + 7, j + 9, k + 11, 0);
	world.setBlock(i + 7, j + 9, k + 12, 4);
	world.setBlock(i + 7, j + 10, k + 0, 0);
	world.setBlock(i + 7, j + 10, k + 1, 0);
	world.setBlock(i + 7, j + 10, k + 2, 5);
	world.setBlock(i + 7, j + 10, k + 3, 0);
	world.setBlock(i + 7, j + 10, k + 4, 0);
	world.setBlock(i + 7, j + 10, k + 5, 0);
	world.setBlock(i + 7, j + 10, k + 6, 5);
	world.setBlock(i + 7, j + 10, k + 7, 5);
	world.setBlock(i + 7, j + 10, k + 8, 53);
	world.setBlockMetadata(i + 7, j + 10, k + 8, 3);
	world.setBlock(i + 7, j + 10, k + 9, 0);
	world.setBlock(i + 7, j + 10, k + 10, 4);
	world.setBlock(i + 7, j + 10, k + 11, 0);
	world.setBlock(i + 7, j + 10, k + 12, 4);
	world.setBlock(i + 7, j + 11, k + 0, 0);
	world.setBlock(i + 7, j + 11, k + 1, 53);
	world.setBlockMetadata(i + 7, j + 11, k + 1, 2);
	world.setBlock(i + 7, j + 11, k + 2, 5);
	world.setBlock(i + 7, j + 11, k + 3, 0);
	world.setBlock(i + 7, j + 11, k + 4, 0);
	world.setBlock(i + 7, j + 11, k + 5, 5);
	world.setBlock(i + 7, j + 11, k + 6, 5);
	world.setBlock(i + 7, j + 11, k + 7, 53);
	world.setBlockMetadata(i + 7, j + 11, k + 7, 3);
	world.setBlock(i + 7, j + 11, k + 8, 0);
	world.setBlock(i + 7, j + 11, k + 9, 0);
	world.setBlock(i + 7, j + 11, k + 10, 0);
	world.setBlock(i + 7, j + 11, k + 11, 0);
	world.setBlock(i + 7, j + 11, k + 12, 0);
	world.setBlock(i + 7, j + 12, k + 0, 0);
	world.setBlock(i + 7, j + 12, k + 1, 0);
	world.setBlock(i + 7, j + 12, k + 2, 53);
	world.setBlockMetadata(i + 7, j + 12, k + 2, 2);
	world.setBlock(i + 7, j + 12, k + 3, 5);
	world.setBlock(i + 7, j + 12, k + 4, 5);
	world.setBlock(i + 7, j + 12, k + 5, 5);
	world.setBlock(i + 7, j + 12, k + 6, 53);
	world.setBlockMetadata(i + 7, j + 12, k + 6, 3);
	world.setBlock(i + 7, j + 12, k + 7, 0);
	world.setBlock(i + 7, j + 12, k + 8, 0);
	world.setBlock(i + 7, j + 12, k + 9, 0);
	world.setBlock(i + 7, j + 12, k + 10, 4);
	world.setBlock(i + 7, j + 12, k + 11, 4);
	world.setBlock(i + 7, j + 12, k + 12, 4);
	world.setBlock(i + 7, j + 13, k + 0, 0);
	world.setBlock(i + 7, j + 13, k + 1, 0);
	world.setBlock(i + 7, j + 13, k + 2, 0);
	world.setBlock(i + 7, j + 13, k + 3, 53);
	world.setBlockMetadata(i + 7, j + 13, k + 3, 2);
	world.setBlock(i + 7, j + 13, k + 4, 5);
	world.setBlock(i + 7, j + 13, k + 5, 53);
	world.setBlockMetadata(i + 7, j + 13, k + 5, 3);
	world.setBlock(i + 7, j + 13, k + 6, 0);
	world.setBlock(i + 7, j + 13, k + 7, 0);
	world.setBlock(i + 7, j + 13, k + 8, 0);
	world.setBlock(i + 7, j + 13, k + 9, 0);
	world.setBlock(i + 7, j + 13, k + 10, 0);
	world.setBlock(i + 7, j + 13, k + 11, 4);
	world.setBlock(i + 7, j + 13, k + 12, 0);
	world.setBlock(i + 8, j + 0, k + 0, 3);
	world.setBlock(i + 8, j + 0, k + 1, 3);
	world.setBlock(i + 8, j + 0, k + 2, 3);
	world.setBlock(i + 8, j + 0, k + 3, 3);
	world.setBlock(i + 8, j + 0, k + 4, 3);
	world.setBlock(i + 8, j + 0, k + 5, 4);
	world.setBlock(i + 8, j + 0, k + 6, 0);
	world.setBlock(i + 8, j + 0, k + 7, 0);
	world.setBlock(i + 8, j + 0, k + 8, 0);
	world.setBlock(i + 8, j + 0, k + 9, 0);
	world.setBlock(i + 8, j + 0, k + 10, 4);
	world.setBlock(i + 8, j + 0, k + 11, 3);
	world.setBlock(i + 8, j + 0, k + 12, 3);
	world.setBlock(i + 8, j + 1, k + 0, 0);
	world.setBlock(i + 8, j + 1, k + 1, 0);
	world.setBlock(i + 8, j + 1, k + 2, 4);
	world.setBlock(i + 8, j + 1, k + 3, 4);
	world.setBlock(i + 8, j + 1, k + 4, 4);
	world.setBlock(i + 8, j + 1, k + 5, 4);
	world.setBlock(i + 8, j + 1, k + 6, 4);
	world.setBlock(i + 8, j + 1, k + 7, 4);
	world.setBlock(i + 8, j + 1, k + 8, 4);
	world.setBlock(i + 8, j + 1, k + 9, 4);
	world.setBlock(i + 8, j + 1, k + 10, 4);
	world.setBlock(i + 8, j + 1, k + 11, 87);
	world.setBlock(i + 8, j + 1, k + 12, 4);
	world.setBlock(i + 8, j + 2, k + 0, 0);
	world.setBlock(i + 8, j + 2, k + 1, 0);
	world.setBlock(i + 8, j + 2, k + 2, 5);
	world.setBlock(i + 8, j + 2, k + 3, 0);
	world.setBlock(i + 8, j + 2, k + 4, 0);
	world.setBlock(i + 8, j + 2, k + 5, 0);
	world.setBlock(i + 8, j + 2, k + 6, 0);
	world.setBlock(i + 8, j + 2, k + 7, 0);
	world.setBlock(i + 8, j + 2, k + 8, 0);
	world.setBlock(i + 8, j + 2, k + 9, 0);
	world.setBlock(i + 8, j + 2, k + 10, 0);
	world.setBlock(i + 8, j + 2, k + 11, 51);
	world.setBlockMetadata(i + 8, j + 2, k + 11, 15);
	world.setBlock(i + 8, j + 2, k + 12, 4);
	world.setBlock(i + 8, j + 3, k + 0, 0);
	world.setBlock(i + 8, j + 3, k + 1, 0);
	world.setBlock(i + 8, j + 3, k + 2, 5);
	world.setBlock(i + 8, j + 3, k + 3, 0);
	world.setBlock(i + 8, j + 3, k + 4, 0);
	world.setBlock(i + 8, j + 3, k + 5, 0);
	world.setBlock(i + 8, j + 3, k + 6, 0);
	world.setBlock(i + 8, j + 3, k + 7, 0);
	world.setBlock(i + 8, j + 3, k + 8, 0);
	world.setBlock(i + 8, j + 3, k + 9, 0);
	world.setBlock(i + 8, j + 3, k + 10, 0);
	world.setBlock(i + 8, j + 3, k + 11, 0);
	world.setBlock(i + 8, j + 3, k + 12, 4);
	world.setBlock(i + 8, j + 4, k + 0, 0);
	world.setBlock(i + 8, j + 4, k + 1, 0);
	world.setBlock(i + 8, j + 4, k + 2, 5);
	world.setBlock(i + 8, j + 4, k + 3, 0);
	world.setBlock(i + 8, j + 4, k + 4, 0);
	world.setBlock(i + 8, j + 4, k + 5, 0);
	world.setBlock(i + 8, j + 4, k + 6, 0);
	world.setBlock(i + 8, j + 4, k + 7, 0);
	world.setBlock(i + 8, j + 4, k + 8, 0);
	world.setBlock(i + 8, j + 4, k + 9, 0);
	world.setBlock(i + 8, j + 4, k + 10, 4);
	world.setBlock(i + 8, j + 4, k + 11, 0);
	world.setBlock(i + 8, j + 4, k + 12, 4);
	world.setBlock(i + 8, j + 5, k + 0, 0);
	world.setBlock(i + 8, j + 5, k + 1, 0);
	world.setBlock(i + 8, j + 5, k + 2, 5);
	world.setBlock(i + 8, j + 5, k + 3, 5);
	world.setBlock(i + 8, j + 5, k + 4, 5);
	world.setBlock(i + 8, j + 5, k + 5, 5);
	world.setBlock(i + 8, j + 5, k + 6, 5);
	world.setBlock(i + 8, j + 5, k + 7, 5);
	world.setBlock(i + 8, j + 5, k + 8, 5);
	world.setBlock(i + 8, j + 5, k + 9, 5);
	world.setBlock(i + 8, j + 5, k + 10, 4);
	world.setBlock(i + 8, j + 5, k + 11, 0);
	world.setBlock(i + 8, j + 5, k + 12, 4);
	world.setBlock(i + 8, j + 6, k + 0, 0);
	world.setBlock(i + 8, j + 6, k + 1, 0);
	world.setBlock(i + 8, j + 6, k + 2, 5);
	world.setBlock(i + 8, j + 6, k + 3, 0);
	world.setBlock(i + 8, j + 6, k + 4, 0);
	world.setBlock(i + 8, j + 6, k + 5, 5);
	world.setBlock(i + 8, j + 6, k + 6, 0);
	world.setBlock(i + 8, j + 6, k + 7, 26);
	world.setBlockMetadata(i + 8, j + 6, k + 7, 3);
	world.setBlock(i + 8, j + 6, k + 8, 26);
	world.setBlockMetadata(i + 8, j + 6, k + 8, 3);
	world.setBlock(i + 8, j + 6, k + 9, 0);
	world.setBlock(i + 8, j + 6, k + 10, 4);
	world.setBlock(i + 8, j + 6, k + 11, 0);
	world.setBlock(i + 8, j + 6, k + 12, 4);
	world.setBlock(i + 8, j + 7, k + 0, 0);
	world.setBlock(i + 8, j + 7, k + 1, 0);
	world.setBlock(i + 8, j + 7, k + 2, 5);
	world.setBlock(i + 8, j + 7, k + 3, 0);
	world.setBlock(i + 8, j + 7, k + 5, 5);
	world.setBlock(i + 8, j + 7, k + 6, 0);
	world.setBlock(i + 8, j + 7, k + 7, 0);
	world.setBlock(i + 8, j + 7, k + 8, 0);
	world.setBlock(i + 8, j + 7, k + 9, 0);
	world.setBlock(i + 8, j + 7, k + 10, 4);
	world.setBlock(i + 8, j + 7, k + 11, 0);
	world.setBlock(i + 8, j + 7, k + 12, 4);
	world.setBlock(i + 8, j + 8, k + 0, 0);
	world.setBlock(i + 8, j + 8, k + 1, 0);
	world.setBlock(i + 8, j + 8, k + 2, 5);
	world.setBlock(i + 8, j + 8, k + 3, 0);
	world.setBlock(i + 8, j + 8, k + 4, 0);
	world.setBlock(i + 8, j + 8, k + 5, 5);
	world.setBlock(i + 8, j + 8, k + 6, 0);
	world.setBlock(i + 8, j + 8, k + 7, 0);
	world.setBlock(i + 8, j + 8, k + 8, 0);
	world.setBlock(i + 8, j + 8, k + 9, 0);
	world.setBlock(i + 8, j + 8, k + 10, 4);
	world.setBlock(i + 8, j + 8, k + 11, 0);
	world.setBlock(i + 8, j + 8, k + 12, 4);
	world.setBlock(i + 8, j + 9, k + 0, 0);
	world.setBlock(i + 8, j + 9, k + 1, 0);
	world.setBlock(i + 8, j + 9, k + 2, 5);
	world.setBlock(i + 8, j + 9, k + 3, 5);
	world.setBlock(i + 8, j + 9, k + 4, 5);
	world.setBlock(i + 8, j + 9, k + 5, 5);
	world.setBlock(i + 8, j + 9, k + 6, 0);
	world.setBlock(i + 8, j + 9, k + 7, 0);
	world.setBlock(i + 8, j + 9, k + 8, 5);
	world.setBlock(i + 8, j + 9, k + 9, 53);
	world.setBlockMetadata(i + 8, j + 9, k + 9, 3);
	world.setBlock(i + 8, j + 9, k + 10, 4);
	world.setBlock(i + 8, j + 9, k + 11, 0);
	world.setBlock(i + 8, j + 9, k + 12, 4);
	world.setBlock(i + 8, j + 10, k + 0, 0);
	world.setBlock(i + 8, j + 10, k + 1, 0);
	world.setBlock(i + 8, j + 10, k + 2, 5);
	world.setBlock(i + 8, j + 10, k + 3, 0);
	world.setBlock(i + 8, j + 10, k + 4, 0);
	world.setBlock(i + 8, j + 10, k + 5, 0);
	world.setBlock(i + 8, j + 10, k + 6, 5);
	world.setBlock(i + 8, j + 10, k + 7, 5);
	world.setBlock(i + 8, j + 10, k + 8, 53);
	world.setBlockMetadata(i + 8, j + 10, k + 8, 3);
	world.setBlock(i + 8, j + 10, k + 9, 0);
	world.setBlock(i + 8, j + 10, k + 10, 4);
	world.setBlock(i + 8, j + 10, k + 11, 0);
	world.setBlock(i + 8, j + 10, k + 12, 4);
	world.setBlock(i + 8, j + 11, k + 0, 0);
	world.setBlock(i + 8, j + 11, k + 1, 53);
	world.setBlockMetadata(i + 8, j + 11, k + 1, 2);
	world.setBlock(i + 8, j + 11, k + 2, 5);
	world.setBlock(i + 8, j + 11, k + 3, 0);
	world.setBlock(i + 8, j + 11, k + 4, 0);
	world.setBlock(i + 8, j + 11, k + 5, 5);
	world.setBlock(i + 8, j + 11, k + 6, 5);
	world.setBlock(i + 8, j + 11, k + 7, 53);
	world.setBlockMetadata(i + 8, j + 11, k + 7, 3);
	world.setBlock(i + 8, j + 11, k + 8, 0);
	world.setBlock(i + 8, j + 11, k + 9, 0);
	world.setBlock(i + 8, j + 11, k + 10, 0);
	world.setBlock(i + 8, j + 11, k + 11, 0);
	world.setBlock(i + 8, j + 11, k + 12, 0);
	world.setBlock(i + 8, j + 12, k + 0, 0);
	world.setBlock(i + 8, j + 12, k + 1, 0);
	world.setBlock(i + 8, j + 12, k + 2, 53);
	world.setBlockMetadata(i + 8, j + 12, k + 2, 2);
	world.setBlock(i + 8, j + 12, k + 3, 5);
	world.setBlock(i + 8, j + 12, k + 4, 5);
	world.setBlock(i + 8, j + 12, k + 5, 5);
	world.setBlock(i + 8, j + 12, k + 6, 53);
	world.setBlockMetadata(i + 8, j + 12, k + 6, 3);
	world.setBlock(i + 8, j + 12, k + 7, 0);
	world.setBlock(i + 8, j + 12, k + 8, 0);
	world.setBlock(i + 8, j + 12, k + 9, 0);
	world.setBlock(i + 8, j + 12, k + 10, 4);
	world.setBlock(i + 8, j + 12, k + 11, 4);
	world.setBlock(i + 8, j + 12, k + 12, 4);
	world.setBlock(i + 8, j + 13, k + 0, 0);
	world.setBlock(i + 8, j + 13, k + 1, 0);
	world.setBlock(i + 8, j + 13, k + 2, 0);
	world.setBlock(i + 8, j + 13, k + 3, 53);
	world.setBlockMetadata(i + 8, j + 13, k + 3, 2);
	world.setBlock(i + 8, j + 13, k + 4, 5);
	world.setBlock(i + 8, j + 13, k + 5, 53);
	world.setBlockMetadata(i + 8, j + 13, k + 5, 3);
	world.setBlock(i + 8, j + 13, k + 6, 0);
	world.setBlock(i + 8, j + 13, k + 7, 0);
	world.setBlock(i + 8, j + 13, k + 8, 0);
	world.setBlock(i + 8, j + 13, k + 9, 0);
	world.setBlock(i + 8, j + 13, k + 10, 0);
	world.setBlock(i + 8, j + 13, k + 11, 4);
	world.setBlock(i + 8, j + 13, k + 12, 0);
	world.setBlock(i + 9, j + 0, k + 0, 3);
	world.setBlock(i + 9, j + 0, k + 1, 2);
	world.setBlock(i + 9, j + 0, k + 2, 3);
	world.setBlock(i + 9, j + 0, k + 3, 3);
	world.setBlock(i + 9, j + 0, k + 4, 3);
	world.setBlock(i + 9, j + 0, k + 5, 4);
	world.setBlock(i + 9, j + 0, k + 6, 0);
	world.setBlock(i + 9, j + 0, k + 7, 0);
	world.setBlock(i + 9, j + 0, k + 8, 0);
	world.setBlock(i + 9, j + 0, k + 9, 0);
	world.setBlock(i + 9, j + 0, k + 10, 4);
	world.setBlock(i + 9, j + 0, k + 11, 3);
	world.setBlock(i + 9, j + 0, k + 12, 2);
	world.setBlock(i + 9, j + 1, k + 0, 0);
	world.setBlock(i + 9, j + 1, k + 1, 0);
	world.setBlock(i + 9, j + 1, k + 2, 4);
	world.setBlock(i + 9, j + 1, k + 3, 4);
	world.setBlock(i + 9, j + 1, k + 4, 4);
	world.setBlock(i + 9, j + 1, k + 5, 4);
	world.setBlock(i + 9, j + 1, k + 6, 4);
	world.setBlock(i + 9, j + 1, k + 7, 4);
	world.setBlock(i + 9, j + 1, k + 8, 4);
	world.setBlock(i + 9, j + 1, k + 9, 4);
	world.setBlock(i + 9, j + 1, k + 10, 4);
	world.setBlock(i + 9, j + 1, k + 11, 4);
	world.setBlock(i + 9, j + 1, k + 12, 0);
	world.setBlock(i + 9, j + 2, k + 0, 0);
	world.setBlock(i + 9, j + 2, k + 1, 0);
	world.setBlock(i + 9, j + 2, k + 2, 5);
	world.setBlock(i + 9, j + 2, k + 3, 0);
	world.setBlock(i + 9, j + 2, k + 4, 0);
	world.setBlock(i + 9, j + 2, k + 5, 0);
	world.setBlock(i + 9, j + 2, k + 6, 0);
	world.setBlock(i + 9, j + 2, k + 7, Block.chest.blockID);
	world.setBlockMetadata(i + 9, j + 2, k + 7, 4);
	world.setBlock(i + 9, j + 2, k + 8, Block.chest.blockID);
	world.setBlockMetadata(i + 9, j + 2, k + 8, 4);
	world.setBlock(i + 9, j + 2, k + 9, 0);
	world.setBlock(i + 9, j + 2, k + 10, 4);
	world.setBlock(i + 9, j + 2, k + 11, 4);
	world.setBlock(i + 9, j + 2, k + 12, 0);
	world.setBlock(i + 9, j + 3, k + 0, 0);
	world.setBlock(i + 9, j + 3, k + 1, 0);
	world.setBlock(i + 9, j + 3, k + 2, 5);
	world.setBlock(i + 9, j + 3, k + 3, 0);
	world.setBlock(i + 9, j + 3, k + 4, 0);
	world.setBlock(i + 9, j + 3, k + 5, 0);
	world.setBlock(i + 9, j + 3, k + 6, 0);
	world.setBlock(i + 9, j + 3, k + 7, 0);
	world.setBlock(i + 9, j + 3, k + 8, 0);
	world.setBlock(i + 9, j + 3, k + 9, 0);
	world.setBlock(i + 9, j + 3, k + 10, 4);
	world.setBlock(i + 9, j + 3, k + 11, 4);
	world.setBlock(i + 9, j + 3, k + 12, 0);
	world.setBlock(i + 9, j + 4, k + 0, 0);
	world.setBlock(i + 9, j + 4, k + 1, 0);
	world.setBlock(i + 9, j + 4, k + 2, 5);
	world.setBlock(i + 9, j + 4, k + 3, 0);
	world.setBlock(i + 9, j + 4, k + 4, 0);
	world.setBlock(i + 9, j + 4, k + 5, 0);
	world.setBlock(i + 9, j + 4, k + 6, 0);
	world.setBlock(i + 9, j + 4, k + 7, 0);
	world.setBlock(i + 9, j + 4, k + 8, 0);
	world.setBlock(i + 9, j + 4, k + 9, 0);
	world.setBlock(i + 9, j + 4, k + 10, 4);
	world.setBlock(i + 9, j + 4, k + 11, 4);
	world.setBlock(i + 9, j + 4, k + 12, 0);
	world.setBlock(i + 9, j + 5, k + 0, 0);
	world.setBlock(i + 9, j + 5, k + 1, 0);
	world.setBlock(i + 9, j + 5, k + 2, 5);
	world.setBlock(i + 9, j + 5, k + 3, 5);
	world.setBlock(i + 9, j + 5, k + 4, 5);
	world.setBlock(i + 9, j + 5, k + 5, 5);
	world.setBlock(i + 9, j + 5, k + 6, 5);
	world.setBlock(i + 9, j + 5, k + 7, 5);
	world.setBlock(i + 9, j + 5, k + 8, 5);
	world.setBlock(i + 9, j + 5, k + 9, 5);
	world.setBlock(i + 9, j + 5, k + 10, 5);
	world.setBlock(i + 9, j + 5, k + 11, 4);
	world.setBlock(i + 9, j + 5, k + 12, 0);
	world.setBlock(i + 9, j + 6, k + 0, 0);
	world.setBlock(i + 9, j + 6, k + 1, 0);
	world.setBlock(i + 9, j + 6, k + 2, 5);
	world.setBlock(i + 9, j + 6, k + 3, Block.chest.blockID);
	world.setBlockMetadata(i + 9, j + 6, k + 3, 4);
	world.setBlock(i + 9, j + 6, k + 4, 54);
	world.setBlockMetadata(i + 9, j + 6, k + 4, 4);
	world.setBlock(i + 9, j + 6, k + 5, 5);
	world.setBlock(i + 9, j + 6, k + 6, 0);
	world.setBlock(i + 9, j + 6, k + 7, 26);
	world.setBlockMetadata(i + 9, j + 6, k + 7, 11);
	world.setBlock(i + 9, j + 6, k + 8, 26);
	world.setBlockMetadata(i + 9, j + 6, k + 8, 11);
	world.setBlock(i + 9, j + 6, k + 9, 0);
	world.setBlockMetadata(i + 9, j + 6, k + 9, 2);
	world.setBlock(i + 9, j + 6, k + 10, 5);
	world.setBlock(i + 9, j + 6, k + 11, 4);
	world.setBlock(i + 9, j + 6, k + 12, 0);
	world.setBlock(i + 9, j + 7, k + 0, 0);
	world.setBlock(i + 9, j + 7, k + 1, 0);
	world.setBlock(i + 9, j + 7, k + 2, 5);
	world.setBlock(i + 9, j + 7, k + 3, 0);
	world.setBlock(i + 9, j + 7, k + 4, 0);
	world.setBlock(i + 9, j + 7, k + 5, 5);
	world.setBlock(i + 9, j + 7, k + 6, 0);
	world.setBlock(i + 9, j + 7, k + 7, 0);
	world.setBlock(i + 9, j + 7, k + 8, 0);
	world.setBlock(i + 9, j + 7, k + 9, 0);
	world.setBlock(i + 9, j + 7, k + 10, 5);
	world.setBlock(i + 9, j + 7, k + 11, 4);
	world.setBlock(i + 9, j + 7, k + 12, 0);
	world.setBlock(i + 9, j + 8, k + 0, 0);
	world.setBlock(i + 9, j + 8, k + 1, 0);
	world.setBlock(i + 9, j + 8, k + 2, 5);
	world.setBlock(i + 9, j + 8, k + 3, 0);
	world.setBlock(i + 9, j + 8, k + 4, 0);
	world.setBlock(i + 9, j + 8, k + 5, 5);
	world.setBlock(i + 9, j + 8, k + 6, 0);
	world.setBlock(i + 9, j + 8, k + 7, 0);
	world.setBlock(i + 9, j + 8, k + 8, 0);
	world.setBlock(i + 9, j + 8, k + 9, 0);
	world.setBlock(i + 9, j + 8, k + 10, 53);
	world.setBlockMetadata(i + 9, j + 8, k + 10, 3);
	world.setBlock(i + 9, j + 8, k + 11, 4);
	world.setBlock(i + 9, j + 8, k + 12, 0);
	world.setBlock(i + 9, j + 9, k + 0, 0);
	world.setBlock(i + 9, j + 9, k + 1, 0);
	world.setBlock(i + 9, j + 9, k + 2, 5);
	world.setBlock(i + 9, j + 9, k + 3, 5);
	world.setBlock(i + 9, j + 9, k + 4, 5);
	world.setBlock(i + 9, j + 9, k + 5, 5);
	world.setBlock(i + 9, j + 9, k + 6, 0);
	world.setBlock(i + 9, j + 9, k + 7, 0);
	world.setBlock(i + 9, j + 9, k + 8, 5);
	world.setBlock(i + 9, j + 9, k + 9, 53);
	world.setBlockMetadata(i + 9, j + 9, k + 9, 3);
	world.setBlock(i + 9, j + 9, k + 10, 0);
	world.setBlock(i + 9, j + 9, k + 11, 4);
	world.setBlock(i + 9, j + 9, k + 12, 0);
	world.setBlock(i + 9, j + 10, k + 0, 0);
	world.setBlock(i + 9, j + 10, k + 1, 0);
	world.setBlock(i + 9, j + 10, k + 2, 5);
	world.setBlock(i + 9, j + 10, k + 3, 0);
	world.setBlock(i + 9, j + 10, k + 4, 0);
	world.setBlock(i + 9, j + 10, k + 5, 0);
	world.setBlock(i + 9, j + 10, k + 6, 5);
	world.setBlock(i + 9, j + 10, k + 7, 5);
	world.setBlock(i + 9, j + 10, k + 8, 53);
	world.setBlockMetadata(i + 9, j + 10, k + 8, 3);
	world.setBlock(i + 9, j + 10, k + 9, 0);
	world.setBlock(i + 9, j + 10, k + 10, 0);
	world.setBlock(i + 9, j + 10, k + 11, 4);
	world.setBlock(i + 9, j + 10, k + 12, 0);
	world.setBlock(i + 9, j + 11, k + 0, 0);
	world.setBlock(i + 9, j + 11, k + 1, 53);
	world.setBlockMetadata(i + 9, j + 11, k + 1, 2);
	world.setBlock(i + 9, j + 11, k + 2, 5);
	world.setBlock(i + 9, j + 11, k + 3, 0);
	world.setBlock(i + 9, j + 11, k + 4, 0);
	world.setBlock(i + 9, j + 11, k + 5, 5);
	world.setBlock(i + 9, j + 11, k + 6, 5);
	world.setBlock(i + 9, j + 11, k + 7, 53);
	world.setBlockMetadata(i + 9, j + 11, k + 7, 3);
	world.setBlock(i + 9, j + 11, k + 8, 0);
	world.setBlock(i + 9, j + 11, k + 9, 0);
	world.setBlock(i + 9, j + 11, k + 10, 0);
	world.setBlock(i + 9, j + 11, k + 11, 85);
	world.setBlock(i + 9, j + 11, k + 12, 0);
	world.setBlock(i + 9, j + 12, k + 0, 0);
	world.setBlock(i + 9, j + 12, k + 1, 0);
	world.setBlock(i + 9, j + 12, k + 2, 53);
	world.setBlockMetadata(i + 9, j + 12, k + 2, 2);
	world.setBlock(i + 9, j + 12, k + 3, 5);
	world.setBlock(i + 9, j + 12, k + 4, 5);
	world.setBlock(i + 9, j + 12, k + 5, 5);
	world.setBlock(i + 9, j + 12, k + 6, 53);
	world.setBlockMetadata(i + 9, j + 12, k + 6, 3);
	world.setBlock(i + 9, j + 12, k + 7, 0);
	world.setBlock(i + 9, j + 12, k + 8, 0);
	world.setBlock(i + 9, j + 12, k + 9, 0);
	world.setBlock(i + 9, j + 12, k + 10, 0);
	world.setBlock(i + 9, j + 12, k + 11, 4);
	world.setBlock(i + 9, j + 12, k + 12, 0);
	world.setBlock(i + 9, j + 13, k + 0, 0);
	world.setBlock(i + 9, j + 13, k + 1, 0);
	world.setBlock(i + 9, j + 13, k + 2, 0);
	world.setBlock(i + 9, j + 13, k + 3, 53);
	world.setBlockMetadata(i + 9, j + 13, k + 3, 2);
	world.setBlock(i + 9, j + 13, k + 4, 5);
	world.setBlock(i + 9, j + 13, k + 5, 53);
	world.setBlockMetadata(i + 9, j + 13, k + 5, 3);
	world.setBlock(i + 9, j + 13, k + 6, 0);
	world.setBlock(i + 9, j + 13, k + 7, 0);
	world.setBlock(i + 9, j + 13, k + 8, 0);
	world.setBlock(i + 9, j + 13, k + 9, 0);
	world.setBlock(i + 9, j + 13, k + 10, 0);
	world.setBlock(i + 9, j + 13, k + 11, 0);
	world.setBlock(i + 9, j + 13, k + 12, 0);
	world.setBlock(i + 10, j + 0, k + 0, 3);
	world.setBlock(i + 10, j + 0, k + 1, 2);
	world.setBlock(i + 10, j + 0, k + 2, 3);
	world.setBlock(i + 10, j + 0, k + 3, 3);
	world.setBlock(i + 10, j + 0, k + 4, 3);
	world.setBlock(i + 10, j + 0, k + 5, 4);
	world.setBlock(i + 10, j + 0, k + 6, 4);
	world.setBlock(i + 10, j + 0, k + 7, 4);
	world.setBlock(i + 10, j + 0, k + 8, 4);
	world.setBlock(i + 10, j + 0, k + 9, 4);
	world.setBlock(i + 10, j + 0, k + 10, 4);
	world.setBlock(i + 10, j + 0, k + 11, 2);
	world.setBlock(i + 10, j + 0, k + 12, 2);
	world.setBlock(i + 10, j + 1, k + 0, 0);
	world.setBlock(i + 10, j + 1, k + 1, 0);
	world.setBlock(i + 10, j + 1, k + 2, 4);
	world.setBlock(i + 10, j + 1, k + 3, 4);
	world.setBlock(i + 10, j + 1, k + 4, 4);
	world.setBlock(i + 10, j + 1, k + 5, 4);
	world.setBlock(i + 10, j + 1, k + 6, 4);
	world.setBlock(i + 10, j + 1, k + 7, 4);
	world.setBlock(i + 10, j + 1, k + 8, 4);
	world.setBlock(i + 10, j + 1, k + 9, 4);
	world.setBlock(i + 10, j + 1, k + 10, 4);
	world.setBlock(i + 10, j + 1, k + 11, 0);
	world.setBlock(i + 10, j + 1, k + 12, 0);
	world.setBlock(i + 10, j + 2, k + 0, 0);
	world.setBlock(i + 10, j + 2, k + 1, 0);
	world.setBlock(i + 10, j + 2, k + 2, 17);
	world.setBlockMetadata(i + 10, j + 2, k + 2, 1);
	world.setBlock(i + 10, j + 2, k + 3, 5);
	world.setBlock(i + 10, j + 2, k + 5, 5);
	world.setBlock(i + 10, j + 2, k + 6, 4);
	world.setBlock(i + 10, j + 2, k + 7, 4);
	world.setBlock(i + 10, j + 2, k + 8, 4);
	world.setBlock(i + 10, j + 2, k + 9, 4);
	world.setBlock(i + 10, j + 2, k + 10, 17);
	world.setBlockMetadata(i + 10, j + 2, k + 10, 1);
	world.setBlock(i + 10, j + 2, k + 11, 0);
	world.setBlock(i + 10, j + 2, k + 12, 0);
	world.setBlock(i + 10, j + 3, k + 0, 0);
	world.setBlock(i + 10, j + 3, k + 1, 0);
	world.setBlock(i + 10, j + 3, k + 2, 17);
	world.setBlockMetadata(i + 10, j + 3, k + 2, 1);
	world.setBlock(i + 10, j + 3, k + 3, 5);
	world.setBlock(i + 10, j + 3, k + 5, 5);
	world.setBlock(i + 10, j + 3, k + 6, 102);
	world.setBlock(i + 10, j + 3, k + 7, 5);
	world.setBlock(i + 10, j + 3, k + 8, 5);
	world.setBlock(i + 10, j + 3, k + 9, 102);
	world.setBlock(i + 10, j + 3, k + 10, 17);
	world.setBlockMetadata(i + 10, j + 3, k + 10, 1);
	world.setBlock(i + 10, j + 3, k + 11, 0);
	world.setBlock(i + 10, j + 3, k + 12, 0);
	world.setBlock(i + 10, j + 4, k + 0, 0);
	world.setBlock(i + 10, j + 4, k + 1, 0);
	world.setBlock(i + 10, j + 4, k + 2, 17);
	world.setBlockMetadata(i + 10, j + 4, k + 2, 1);
	world.setBlock(i + 10, j + 4, k + 3, 5);
	world.setBlock(i + 10, j + 4, k + 4, 5);
	world.setBlock(i + 10, j + 4, k + 5, 5);
	world.setBlock(i + 10, j + 4, k + 6, 102);
	world.setBlock(i + 10, j + 4, k + 7, 5);
	world.setBlock(i + 10, j + 4, k + 8, 5);
	world.setBlock(i + 10, j + 4, k + 9, 102);
	world.setBlock(i + 10, j + 4, k + 10, 17);
	world.setBlockMetadata(i + 10, j + 4, k + 10, 1);
	world.setBlock(i + 10, j + 4, k + 11, 0);
	world.setBlock(i + 10, j + 4, k + 12, 0);
	world.setBlock(i + 10, j + 5, k + 0, 0);
	world.setBlock(i + 10, j + 5, k + 1, 0);
	world.setBlock(i + 10, j + 5, k + 2, 17);
	world.setBlockMetadata(i + 10, j + 5, k + 2, 1);
	world.setBlock(i + 10, j + 5, k + 3, 5);
	world.setBlock(i + 10, j + 5, k + 4, 5);
	world.setBlock(i + 10, j + 5, k + 5, 5);
	world.setBlock(i + 10, j + 5, k + 6, 5);
	world.setBlock(i + 10, j + 5, k + 7, 5);
	world.setBlock(i + 10, j + 5, k + 8, 5);
	world.setBlock(i + 10, j + 5, k + 9, 5);
	world.setBlock(i + 10, j + 5, k + 10, 17);
	world.setBlockMetadata(i + 10, j + 5, k + 10, 1);
	world.setBlock(i + 10, j + 5, k + 11, 0);
	world.setBlock(i + 10, j + 5, k + 12, 0);
	world.setBlock(i + 10, j + 6, k + 0, 0);
	world.setBlock(i + 10, j + 6, k + 1, 0);
	world.setBlock(i + 10, j + 6, k + 2, 17);
	world.setBlockMetadata(i + 10, j + 6, k + 2, 1);
	world.setBlock(i + 10, j + 6, k + 3, 5);
	world.setBlock(i + 10, j + 6, k + 4, 5);
	world.setBlock(i + 10, j + 6, k + 5, 5);
	world.setBlock(i + 10, j + 6, k + 6, 5);
	world.setBlock(i + 10, j + 6, k + 7, 5);
	world.setBlock(i + 10, j + 6, k + 8, 5);
	world.setBlock(i + 10, j + 6, k + 9, 5);
	world.setBlock(i + 10, j + 6, k + 10, 17);
	world.setBlockMetadata(i + 10, j + 6, k + 10, 1);
	world.setBlock(i + 10, j + 6, k + 11, 0);
	world.setBlock(i + 10, j + 6, k + 12, 0);
	world.setBlock(i + 10, j + 7, k + 0, 0);
	world.setBlock(i + 10, j + 7, k + 1, 0);
	world.setBlock(i + 10, j + 7, k + 2, 17);
	world.setBlockMetadata(i + 10, j + 7, k + 2, 1);
	world.setBlock(i + 10, j + 7, k + 3, 5);
	world.setBlock(i + 10, j + 7, k + 4, 5);
	world.setBlock(i + 10, j + 7, k + 5, 5);
	world.setBlock(i + 10, j + 7, k + 6, 102);
	world.setBlock(i + 10, j + 7, k + 7, 5);
	world.setBlock(i + 10, j + 7, k + 8, 5);
	world.setBlock(i + 10, j + 7, k + 9, 102);
	world.setBlock(i + 10, j + 7, k + 10, 17);
	world.setBlockMetadata(i + 10, j + 7, k + 10, 1);
	world.setBlock(i + 10, j + 7, k + 11, 0);
	world.setBlock(i + 10, j + 7, k + 12, 0);
	world.setBlock(i + 10, j + 8, k + 0, 0);
	world.setBlock(i + 10, j + 8, k + 1, 0);
	world.setBlock(i + 10, j + 8, k + 2, 17);
	world.setBlockMetadata(i + 10, j + 8, k + 2, 1);
	world.setBlock(i + 10, j + 8, k + 3, 5);
	world.setBlock(i + 10, j + 8, k + 4, 5);
	world.setBlock(i + 10, j + 8, k + 5, 5);
	world.setBlock(i + 10, j + 8, k + 6, 102);
	world.setBlock(i + 10, j + 8, k + 7, 5);
	world.setBlock(i + 10, j + 8, k + 8, 5);
	world.setBlock(i + 10, j + 8, k + 9, 5);
	world.setBlock(i + 10, j + 8, k + 10, 53);
	world.setBlockMetadata(i + 10, j + 8, k + 10, 3);
	world.setBlock(i + 10, j + 8, k + 11, 0);
	world.setBlock(i + 10, j + 8, k + 12, 0);
	world.setBlock(i + 10, j + 9, k + 0, 0);
	world.setBlock(i + 10, j + 9, k + 1, 0);
	world.setBlock(i + 10, j + 9, k + 2, 17);
	world.setBlockMetadata(i + 10, j + 9, k + 2, 1);
	world.setBlock(i + 10, j + 9, k + 3, 5);
	world.setBlock(i + 10, j + 9, k + 4, 5);
	world.setBlock(i + 10, j + 9, k + 5, 5);
	world.setBlock(i + 10, j + 9, k + 6, 5);
	world.setBlock(i + 10, j + 9, k + 7, 5);
	world.setBlock(i + 10, j + 9, k + 8, 5);
	world.setBlock(i + 10, j + 9, k + 9, 53);
	world.setBlockMetadata(i + 10, j + 9, k + 9, 3);
	world.setBlock(i + 10, j + 9, k + 10, 0);
	world.setBlock(i + 10, j + 9, k + 11, 0);
	world.setBlock(i + 10, j + 9, k + 12, 0);
	world.setBlock(i + 10, j + 10, k + 0, 0);
	world.setBlock(i + 10, j + 10, k + 1, 0);
	world.setBlock(i + 10, j + 10, k + 2, 17);
	world.setBlockMetadata(i + 10, j + 10, k + 2, 1);
	world.setBlock(i + 10, j + 10, k + 3, 5);
	world.setBlock(i + 10, j + 10, k + 4, 102);
	world.setBlock(i + 10, j + 10, k + 5, 5);
	world.setBlock(i + 10, j + 10, k + 6, 5);
	world.setBlock(i + 10, j + 10, k + 7, 5);
	world.setBlock(i + 10, j + 10, k + 8, 53);
	world.setBlockMetadata(i + 10, j + 10, k + 8, 3);
	world.setBlock(i + 10, j + 10, k + 9, 0);
	world.setBlock(i + 10, j + 10, k + 10, 0);
	world.setBlock(i + 10, j + 10, k + 11, 0);
	world.setBlock(i + 10, j + 10, k + 12, 0);
	world.setBlock(i + 10, j + 11, k + 0, 0);
	world.setBlock(i + 10, j + 11, k + 1, 53);
	world.setBlockMetadata(i + 10, j + 11, k + 1, 2);
	world.setBlock(i + 10, j + 11, k + 2, 17);
	world.setBlockMetadata(i + 10, j + 11, k + 2, 1);
	world.setBlock(i + 10, j + 11, k + 3, 5);
	world.setBlock(i + 10, j + 11, k + 4, 102);
	world.setBlock(i + 10, j + 11, k + 5, 5);
	world.setBlock(i + 10, j + 11, k + 6, 5);
	world.setBlock(i + 10, j + 11, k + 7, 53);
	world.setBlockMetadata(i + 10, j + 11, k + 7, 3);
	world.setBlock(i + 10, j + 11, k + 8, 0);
	world.setBlock(i + 10, j + 11, k + 9, 0);
	world.setBlock(i + 10, j + 11, k + 10, 0);
	world.setBlock(i + 10, j + 11, k + 11, 0);
	world.setBlock(i + 10, j + 11, k + 12, 0);
	world.setBlock(i + 10, j + 12, k + 0, 0);
	world.setBlock(i + 10, j + 12, k + 1, 0);
	world.setBlock(i + 10, j + 12, k + 2, 53);
	world.setBlockMetadata(i + 10, j + 12, k + 2, 2);
	world.setBlock(i + 10, j + 12, k + 3, 5);
	world.setBlock(i + 10, j + 12, k + 4, 5);
	world.setBlock(i + 10, j + 12, k + 5, 5);
	world.setBlock(i + 10, j + 12, k + 6, 53);
	world.setBlockMetadata(i + 10, j + 12, k + 6, 3);
	world.setBlock(i + 10, j + 12, k + 7, 0);
	world.setBlock(i + 10, j + 12, k + 8, 0);
	world.setBlock(i + 10, j + 12, k + 9, 0);
	world.setBlock(i + 10, j + 12, k + 10, 0);
	world.setBlock(i + 10, j + 12, k + 11, 0);
	world.setBlock(i + 10, j + 12, k + 12, 0);
	world.setBlock(i + 10, j + 13, k + 0, 0);
	world.setBlock(i + 10, j + 13, k + 1, 0);
	world.setBlock(i + 10, j + 13, k + 2, 0);
	world.setBlock(i + 10, j + 13, k + 3, 53);
	world.setBlockMetadata(i + 10, j + 13, k + 3, 2);
	world.setBlock(i + 10, j + 13, k + 4, 5);
	world.setBlock(i + 10, j + 13, k + 5, 53);
	world.setBlockMetadata(i + 10, j + 13, k + 5, 3);
	world.setBlock(i + 10, j + 13, k + 6, 0);
	world.setBlock(i + 10, j + 13, k + 7, 0);
	world.setBlock(i + 10, j + 13, k + 8, 0);
	world.setBlock(i + 10, j + 13, k + 9, 0);
	world.setBlock(i + 10, j + 13, k + 10, 0);
	world.setBlock(i + 10, j + 13, k + 11, 0);
	world.setBlock(i + 10, j + 13, k + 12, 0);
	world.setBlock(i + 11, j + 0, k + 0, 3);
	world.setBlock(i + 11, j + 0, k + 1, 2);
	world.setBlock(i + 11, j + 0, k + 2, 2);
	world.setBlock(i + 11, j + 0, k + 3, 2);
	world.setBlock(i + 11, j + 0, k + 4, 3);
	world.setBlock(i + 11, j + 0, k + 5, 2);
	world.setBlock(i + 11, j + 0, k + 6, 2);
	world.setBlock(i + 11, j + 0, k + 7, 2);
	world.setBlock(i + 11, j + 0, k + 8, 2);
	world.setBlock(i + 11, j + 0, k + 9, 2);
	world.setBlock(i + 11, j + 0, k + 10, 2);
	world.setBlock(i + 11, j + 0, k + 11, 2);
	world.setBlock(i + 11, j + 0, k + 12, 0);
	world.setBlock(i + 11, j + 1, k + 0, 0);
	world.setBlock(i + 11, j + 1, k + 1, 0);
	world.setBlock(i + 11, j + 1, k + 2, 0);
	world.setBlock(i + 11, j + 1, k + 3, 0);
	world.setBlock(i + 11, j + 1, k + 4, 109);
	world.setBlockMetadata(i + 11, j + 1, k + 4, 1);
	world.setBlock(i + 11, j + 1, k + 5, 0);
	world.setBlock(i + 11, j + 1, k + 6, 0);
	world.setBlock(i + 11, j + 1, k + 7, 0);
	world.setBlock(i + 11, j + 1, k + 8, 0);
	world.setBlock(i + 11, j + 1, k + 9, 0);
	world.setBlock(i + 11, j + 1, k + 10, 0);
	world.setBlock(i + 11, j + 1, k + 11, 0);
	world.setBlock(i + 11, j + 1, k + 12, 0);
	world.setBlock(i + 11, j + 2, k + 0, 0);
	world.setBlock(i + 11, j + 2, k + 1, 0);
	world.setBlock(i + 11, j + 2, k + 2, 0);
	world.setBlock(i + 11, j + 2, k + 3, 0);
	world.setBlock(i + 11, j + 2, k + 4, 0);
	world.setBlock(i + 11, j + 2, k + 6, 3);
	world.setBlock(i + 11, j + 2, k + 9, 3);
	world.setBlock(i + 11, j + 2, k + 11, 0);
	world.setBlock(i + 11, j + 2, k + 12, 0);
	world.setBlock(i + 11, j + 3, k + 0, 0);
	world.setBlock(i + 11, j + 3, k + 1, 0);
	world.setBlock(i + 11, j + 3, k + 2, 0);
	world.setBlock(i + 11, j + 3, k + 4, 0);
	world.setBlock(i + 11, j + 3, k + 7, 0);
	world.setBlock(i + 11, j + 3, k + 8, 0);
	world.setBlock(i + 11, j + 3, k + 10, 0);
	world.setBlock(i + 11, j + 3, k + 11, 0);
	world.setBlock(i + 11, j + 3, k + 12, 0);
	world.setBlock(i + 11, j + 4, k + 0, 0);
	world.setBlock(i + 11, j + 4, k + 1, 0);
	world.setBlock(i + 11, j + 4, k + 2, 0);
	world.setBlock(i + 11, j + 4, k + 3, 0);
	world.setBlock(i + 11, j + 4, k + 4, 0);
	world.setBlock(i + 11, j + 4, k + 5, 0);
	world.setBlock(i + 11, j + 4, k + 6, 0);
	world.setBlock(i + 11, j + 4, k + 7, 0);
	world.setBlock(i + 11, j + 4, k + 8, 0);
	world.setBlock(i + 11, j + 4, k + 9, 0);
	world.setBlock(i + 11, j + 4, k + 10, 0);
	world.setBlock(i + 11, j + 4, k + 11, 0);
	world.setBlock(i + 11, j + 4, k + 12, 0);
	world.setBlock(i + 11, j + 5, k + 0, 0);
	world.setBlock(i + 11, j + 5, k + 1, 0);
	world.setBlock(i + 11, j + 5, k + 2, 0);
	world.setBlock(i + 11, j + 5, k + 3, 53);
	world.setBlockMetadata(i + 11, j + 5, k + 3, 2);
	world.setBlock(i + 11, j + 5, k + 4, 5);
	world.setBlock(i + 11, j + 5, k + 5, 53);
	world.setBlockMetadata(i + 11, j + 5, k + 5, 3);
	world.setBlock(i + 11, j + 5, k + 6, 0);
	world.setBlock(i + 11, j + 5, k + 7, 0);
	world.setBlock(i + 11, j + 5, k + 8, 0);
	world.setBlock(i + 11, j + 5, k + 9, 0);
	world.setBlock(i + 11, j + 5, k + 10, 0);
	world.setBlock(i + 11, j + 5, k + 11, 0);
	world.setBlock(i + 11, j + 5, k + 12, 0);
	world.setBlock(i + 11, j + 6, k + 0, 0);
	world.setBlock(i + 11, j + 6, k + 1, 0);
	world.setBlock(i + 11, j + 6, k + 2, 0);
	world.setBlock(i + 11, j + 6, k + 3, 0);
	world.setBlock(i + 11, j + 6, k + 4, 53);
	world.setBlockMetadata(i + 11, j + 6, k + 4, 1);
	world.setBlock(i + 11, j + 6, k + 6, 3);
	world.setBlock(i + 11, j + 6, k + 8, 0);
	world.setBlock(i + 11, j + 6, k + 9, 0);
	world.setBlock(i + 11, j + 6, k + 10, 0);
	world.setBlock(i + 11, j + 6, k + 11, 0);
	world.setBlock(i + 11, j + 6, k + 12, 0);
	world.setBlock(i + 11, j + 7, k + 0, 0);
	world.setBlock(i + 11, j + 7, k + 1, 0);
	world.setBlock(i + 11, j + 7, k + 2, 0);
	world.setBlock(i + 11, j + 7, k + 3, 0);
	world.setBlock(i + 11, j + 7, k + 4, 0);
	world.setBlock(i + 11, j + 7, k + 5, 0);
	world.setBlock(i + 11, j + 7, k + 7, 0);
	world.setBlock(i + 11, j + 7, k + 8, 0);
	world.setBlock(i + 11, j + 7, k + 9, 0);
	world.setBlock(i + 11, j + 7, k + 10, 0);
	world.setBlock(i + 11, j + 7, k + 11, 0);
	world.setBlock(i + 11, j + 7, k + 12, 0);
	world.setBlock(i + 11, j + 8, k + 0, 0);
	world.setBlock(i + 11, j + 8, k + 1, 0);
	world.setBlock(i + 11, j + 8, k + 2, 0);
	world.setBlock(i + 11, j + 8, k + 3, 0);
	world.setBlock(i + 11, j + 8, k + 4, 0);
	world.setBlock(i + 11, j + 8, k + 5, 0);
	world.setBlock(i + 11, j + 8, k + 6, 0);
	world.setBlock(i + 11, j + 8, k + 7, 0);
	world.setBlock(i + 11, j + 8, k + 8, 0);
	world.setBlock(i + 11, j + 8, k + 9, 0);
	world.setBlock(i + 11, j + 8, k + 10, 53);
	world.setBlockMetadata(i + 11, j + 8, k + 10, 3);
	world.setBlock(i + 11, j + 8, k + 11, 0);
	world.setBlock(i + 11, j + 8, k + 12, 0);
	world.setBlock(i + 11, j + 9, k + 0, 0);
	world.setBlock(i + 11, j + 9, k + 1, 0);
	world.setBlock(i + 11, j + 9, k + 2, 0);
	world.setBlock(i + 11, j + 9, k + 3, 0);
	world.setBlock(i + 11, j + 9, k + 4, 0);
	world.setBlock(i + 11, j + 9, k + 5, 0);
	world.setBlock(i + 11, j + 9, k + 6, 53);
	world.setBlockMetadata(i + 11, j + 9, k + 6, 5);
	world.setBlock(i + 11, j + 9, k + 7, 0);
	world.setBlock(i + 11, j + 9, k + 8, 0);
	world.setBlock(i + 11, j + 9, k + 9, 53);
	world.setBlockMetadata(i + 11, j + 9, k + 9, 3);
	world.setBlock(i + 11, j + 9, k + 10, 0);
	world.setBlock(i + 11, j + 9, k + 11, 0);
	world.setBlock(i + 11, j + 9, k + 12, 0);
	world.setBlock(i + 11, j + 10, k + 0, 0);
	world.setBlock(i + 11, j + 10, k + 1, 0);
	world.setBlock(i + 11, j + 10, k + 2, 0);
	world.setBlock(i + 11, j + 10, k + 3, 0);
	world.setBlock(i + 11, j + 10, k + 4, 0);
	world.setBlock(i + 11, j + 10, k + 5, 0);
	world.setBlock(i + 11, j + 10, k + 6, 5);
	world.setBlock(i + 11, j + 10, k + 7, 0);
	world.setBlock(i + 11, j + 10, k + 8, 53);
	world.setBlockMetadata(i + 11, j + 10, k + 8, 3);
	world.setBlock(i + 11, j + 10, k + 9, 0);
	world.setBlock(i + 11, j + 10, k + 10, 0);
	world.setBlock(i + 11, j + 10, k + 11, 0);
	world.setBlock(i + 11, j + 10, k + 12, 0);
	world.setBlock(i + 11, j + 11, k + 0, 0);
	world.setBlock(i + 11, j + 11, k + 1, 53);
	world.setBlockMetadata(i + 11, j + 11, k + 1, 2);
	world.setBlock(i + 11, j + 11, k + 2, 0);
	world.setBlock(i + 11, j + 11, k + 3, 0);
	world.setBlock(i + 11, j + 11, k + 4, 0);
	world.setBlock(i + 11, j + 11, k + 5, 0);
	world.setBlock(i + 11, j + 11, k + 6, 0);
	world.setBlock(i + 11, j + 11, k + 7, 53);
	world.setBlockMetadata(i + 11, j + 11, k + 7, 3);
	world.setBlock(i + 11, j + 11, k + 8, 0);
	world.setBlock(i + 11, j + 11, k + 9, 0);
	world.setBlock(i + 11, j + 11, k + 10, 0);
	world.setBlock(i + 11, j + 11, k + 11, 0);
	world.setBlock(i + 11, j + 11, k + 12, 0);
	world.setBlock(i + 11, j + 12, k + 0, 0);
	world.setBlock(i + 11, j + 12, k + 1, 0);
	world.setBlock(i + 11, j + 12, k + 2, 53);
	world.setBlockMetadata(i + 11, j + 12, k + 2, 2);
	world.setBlock(i + 11, j + 12, k + 3, 0);
	world.setBlock(i + 11, j + 12, k + 4, 5);
	world.setBlock(i + 11, j + 12, k + 5, 0);
	world.setBlock(i + 11, j + 12, k + 6, 53);
	world.setBlockMetadata(i + 11, j + 12, k + 6, 3);
	world.setBlock(i + 11, j + 12, k + 7, 0);
	world.setBlock(i + 11, j + 12, k + 8, 0);
	world.setBlock(i + 11, j + 12, k + 9, 0);
	world.setBlock(i + 11, j + 12, k + 10, 0);
	world.setBlock(i + 11, j + 12, k + 11, 0);
	world.setBlock(i + 11, j + 12, k + 12, 0);
	world.setBlock(i + 11, j + 13, k + 0, 0);
	world.setBlock(i + 11, j + 13, k + 1, 0);
	world.setBlock(i + 11, j + 13, k + 2, 0);
	world.setBlock(i + 11, j + 13, k + 3, 53);
	world.setBlockMetadata(i + 11, j + 13, k + 3, 2);
	world.setBlock(i + 11, j + 13, k + 4, 5);
	world.setBlock(i + 11, j + 13, k + 5, 53);
	world.setBlockMetadata(i + 11, j + 13, k + 5, 3);
	world.setBlock(i + 11, j + 13, k + 6, 0);
